Workbook

Sheet Resumen
A1: RESUMEN · EQUIPO 48 · Entrega 1 (AF + ACS) · Hotel 3* Barcelona
A2: Todos los valores son fórmulas enlazadas a las hojas de cálculo.
A4: Concepto | B4: Valor | C4: Unidad / detalle
A5: Suministro | B5: Mixto DIR+ALJ
A6: Plantas en directo | B6: PB a P7 | C6: Recorridos R1-R4: presión mínima en grifo P7
A7: Presión mínima en grifo más desfavorable en directo | B7: =MIN(Recorridos!F5:F8) | C7: mca (≥10)
A8: Plantas con bombeo | B8: P8 a P11 | C8: 1 estación de bombeo BVV aspirando de aljibe
A9: Caudal simultáneo instalación general (Qc) | B9: =INDEX(Tramos!$K$5:$K$112,MATCH("G1",Tramos!$A$5:$A$112,0)) | C9: l/s
A10: Acometida / tubo de alimentación | B10: =INDEX(Tramos!$N$5:$N$112,MATCH("G1",Tramos!$A$5:$A$112,0)) | C10: PE100 SDR11 PN16
A11: Contador general | B11: =INDEX(Tramos!$N$5:$N$112,MATCH("E1",Tramos!$A$5:$A$112,0)) | C11: Woltman (velocidad 0,8-1,2 m/s)
A12: Válvula de retención general | B12: =INDEX(Tramos!$N$5:$N$112,MATCH("E2",Tramos!$A$5:$A$112,0))
A13: Filtro general | B13: =INDEX(Tramos!$N$5:$N$112,MATCH("E4",Tramos!$A$5:$A$112,0))
A14: Montante directo O (tramo inicial) | B14: =INDEX(Tramos!$N$5:$N$112,MATCH("MDL1",Tramos!$A$5:$A$112,0)) | C14: multicapa
A15: Montante bombeo O (tramo inicial) | B15: =INDEX(Tramos!$N$5:$N$112,MATCH("MBL8",Tramos!$A$5:$A$112,0)) | C15: multicapa
A16: Montante ACS alta O (tramo inicial) | B16: =INDEX(Tramos!$N$5:$N$112,MATCH("MCAL8",Tramos!$A$5:$A$112,0)) | C16: multicapa
A17: Montante ACS baja O (tramo inicial) | B17: =INDEX(Tramos!$N$5:$N$112,MATCH("MCBL1",Tramos!$A$5:$A$112,0)) | C17: multicapa
A18: Presión a mantener en calderín (BVV) | B18: =Bombeo!B5 | C18: mca
A19: Caudal de bombeo | B19: =Bombeo!B6 | C19: l/s
A20: Nº de bombas | B20: =Bombeo!B8&" + 1 reserva"
A21: Altura de bombeo | B21: =Bombeo!B11 | C21: mca
A22: Potencia eléctrica por bomba | B22: =Bombeo!B14 | C22: kW
A23: Calderín | B23: =Bombeo!B15 | C23: l
A24: Presión estática máxima (bombeo, planta más baja) | B24: =Bombeo!B16 | C24: mca (<50)
A25: Tarado válvula reductora ACS baja | B25: =Bombeo!B19 | C25: mca
A26: Aljibe | B26: =Bombeo!B25&" vasos × "&Bombeo!B27&" l" | C26: =Bombeo!B29
A27: Demanda ACS | B27: =ACS!B8 | C27: l/día a 60 ºC
A28: Contribución renovable exigida / obtenida | B28: =TEXT(ACS!B9,"0%")&" / "&TEXT(ACS!B12,"0%") | C28: =ACS!B13
A29: Potencia bombas de calor | B29: =ACS!B17 | C29: kW
A30: Volumen de acumulación ACS | B30: =ACS!B18 | C30: l
A33: Hipótesis pendientes de confirmar (celdas amarillas): coeficientes UNE hotel (Datos), K de elementos singulares (Datos), SCOP y T agua fría (ACS), ocupación 2 pers/hab.

Sheet Datos
A1: TRABAJO INSTALACIONES DE FLUIDOS 2026-27 · EQUIPO 48 · Hotel 3*
A2: Leyenda: texto azul = dato de entrada (editable) · negro = fórmula · fondo amarillo = hipótesis a confirmar con el tutor
A4: Parámetro | B4: Valor | C4: Unidad | D4: Fuente / nota
A5: Equipo | B5: 48 | D5: Enunciado, Anexo I
A6: Tipo de suministro | B6: Mixto (DIR+ALJ) | D6: Enunciado, Anexo I
A7: Presión de red (a cota calzada 0,00) | B7: 40 | C7: mca | D7: Enunciado, Anexo I
A8: Plantas por encima de PB | B8: 11 | D8: Enunciado, Anexo I
A9: Emplazamiento | B9: Barcelona | D9: Enunciado, Anexo I
A10: Acometidas | B10: Este/Oeste | D10: Enunciado, Anexo I
A11: Cota calzada | B11: 0 | C11: m | D11: Plano esquema vertical
A12: Cota solera PB | B12: 0.3 | C12: m | D12: Enunciado cond. 6
A13: Altura PB (solera PB a solera P1) | B13: 4.1 | C13: m | D13: Enunciado cond. 6
A14: Altura planta tipo (solera a solera) | B14: 3.3 | C14: m | D14: Enunciado cond. 6
A15: Altura conexión aparatos sobre solera | B15: 0.6 | C15: m | D15: Enunciado cond. 32
A16: Cota solera sótano | B16: -2.2 | C16: m | D16: Esquema vertical DWG: cota 2,198 m bajo calzada 0,00 (rampa 12 m al 18 % = 2,16 m)
A17: Mayoración longitudes (f L-eq) | B17: 1.3 | D17: Enunciado cond. 33
A18: Presión mínima en grifo | B18: 10 | C18: mca | D18: CTE DB-HS4 2.1.3
A19: Presión máxima en grifo | B19: 50 | C19: mca | D19: CTE DB-HS4 2.1.3
A20: Diferencial calderín (BVF) Δp | B20: 20 | C20: mca | D20: Procedimiento diseño UPV
A23: Simultaneidad UNE 149201 · Hoteles, discotecas, museos: Qc = A·Qt^B + C (l/s)
A24: Rango | B24: A | C24: B | D24: C
A25: Qt ≤ 20 l/s | B25: 0.698 | C25: 0.5 | D25: -0.12
A26: Qt > 20 l/s | B26: 1 | C26: 0.366 | D26: 0
A29: Caudales instantáneos mínimos · CTE DB-HS4 Tabla 2.1
A30: Aparato | B30: Q AF (l/s) | C30: Q ACS (l/s) | D30: Nota
A31: Lavabo | B31: 0.1 | C31: 0.065
A32: Ducha | B32: 0.2 | C32: 0.1
A33: Bañera ≥ 1,40 m | B33: 0.3 | C33: 0.2 | D33: Bañeras del hotel ≈1,70 m (medido en DWG)
A34: Bidé | B34: 0.1 | C34: 0.065
A35: Inodoro con cisterna | B35: 0.1 | C35: 0
A36: Urinario con cisterna | B36: 0.04 | C36: 0
A37: Fregadero no doméstico | B37: 0.3 | C37: 0.2
A38: Lavavajillas industrial (20 serv.) | B38: 0.25 | C38: 0.2 | D38: Bitérmico (enunciado cond. 15)
A39: Vertedero | B39: 0.2 | C39: 0
A40: Grifo garaje / limpieza | B40: 0.2 | C40: 0
A43: Parámetros hidráulicos y cotas de cálculo | F43: Coeficientes K de elementos singulares (HIPÓTESIS hasta tener la tabla del profesor)
A44: Parámetro | B44: Valor | C44: Unidad | D44: Fuente / nota | F44: Elemento | G44: K
A45: Gravedad g | B45: 9.81 | C45: m/s² | F45: Llave de corte / aislamiento (bola) | G45: 0.3
A46: Viscosidad cinemática AF (20 ºC) | B46: 1.004e-06 | C46: m²/s | D46: Propiedades del agua | F46: Válvula de retención | G46: 2.5
A47: Viscosidad cinemática ACS (60 ºC) | B47: 4.74e-07 | C47: m²/s | D47: Propiedades del agua | F47: Filtro | G47: 5
...

Sheet Locales
A1: Aparatos por tipo de local (contados sobre el DWG HOTEL_Trabajo_2026-27)
A3: Local | B3: Lavabo | C3: Ducha | D3: Bañera ≥ 1,40 m | E3: Bidé | F3: Inodoro con cisterna | G3: Urinario con cisterna | H3: Fregadero no doméstico | I3: Lavavajillas industrial (20 serv.) | J3: Vertedero | K3: Grifo garaje / limpieza | L3: Qt AF (l/s) | M3: Qt ACS (l/s) | N3: Qt AF+ACS (l/s) | O3: Observaciones
A4: Habitación estándar | B4: 1 | C4: 0 | D4: 1 | E4: 1 | F4: 1 | G4: 0 | H4: 0 | I4: 0 | J4: 0 | K4: 0 | L4: =B4*Datos!$B$31+C4*Datos!$B$32+D4*Datos!$B$33+E4*Datos!$B$34+F4*Datos!$B$35+G4*Datos!$B$36+H4*Datos!$B$37+I4*Datos!$B$38+J4*Datos!$B$39+K4*Datos!$B$40 | M4: =B4*Datos!$C$31+C4*Datos!$C$32+D4*Datos!$C$33+E4*Datos!$C$34+F4*Datos!$C$35+G4*Datos!$C$36+H4*Datos!$C$37+I4*Datos!$C$38+J4*Datos!$C$39+K4*Datos!$C$40 | N4: =L4+M4 | O4: 24 por planta tipo, 5 en PB
A5: Habitación adaptada | B5: 1 | C5: 1 | D5: 0 | E5: 0 | F5: 1 | G5: 0 | H5: 0 | I5: 0 | J5: 0 | K5: 0 | L5: =B5*Datos!$B$31+C5*Datos!$B$32+D5*Datos!$B$33+E5*Datos!$B$34+F5*Datos!$B$35+G5*Datos!$B$36+H5*Datos!$B$37+I5*Datos!$B$38+J5*Datos!$B$39+K5*Datos!$B$40 | M5: =B5*Datos!$C$31+C5*Datos!$C$32+D5*Datos!$C$33+E5*Datos!$C$34+F5*Datos!$C$35+G5*Datos!$C$36+H5*Datos!$C$37+I5*Datos!$C$38+J5*Datos!$C$39+K5*Datos!$C$40 | N5: =L5+M5 | O5: Ducha a ras de suelo con sumidero. 2 por planta tipo, 2 en PB (004, 006)
A6: Oficio de planta (21) | B6: 0 | C6: 0 | D6: 0 | E6: 0 | F6: 0 | G6: 0 | H6: 1 | I6: 0 | J6: 1 | K6: 0 | L6: =B6*Datos!$B$31+C6*Datos!$B$32+D6*Datos!$B$33+E6*Datos!$B$34+F6*Datos!$B$35+G6*Datos!$B$36+H6*Datos!$B$37+I6*Datos!$B$38+J6*Datos!$B$39+K6*Datos!$B$40 | M6: =B6*Datos!$C$31+C6*Datos!$C$32+D6*Datos!$C$33+E6*Datos!$C$34+F6*Datos!$C$35+G6*Datos!$C$36+H6*Datos!$C$37+I6*Datos!$C$38+J6*Datos!$C$39+K6*Datos!$C$40 | N6: =L6+M6 | O6: Leyenda: fregadero + vertedero
A7: Aseo público hombres (8) | B7: 2 | C7: 0 | D7: 0 | E7: 0 | F7: 2 | G7: 2 | H7: 0 | I7: 0 | J7: 0 | K7: 0 | L7: =B7*Datos!$B$31+C7*Datos!$B$32+D7*Datos!$B$33+E7*Datos!$B$34+F7*Datos!$B$35+G7*Datos!$B$36+H7*Datos!$B$37+I7*Datos!$B$38+J7*Datos!$B$39+K7*Datos!$B$40 | M7: =B7*Datos!$C$31+C7*Datos!$C$32+D7*Datos!$C$33+E7*Datos!$C$34+F7*Datos!$C$35+G7*Datos!$C$36+H7*Datos!$C$37+I7*Datos!$C$38+J7*Datos!$C$39+K7*Datos!$C$40 | N7: =L7+M7 | O7: 2 urinarios dibujados en el aseo derecho
A8: Aseo público mujeres (8) | B8: 2 | C8: 0 | D8: 0 | E8: 0 | F8: 2 | G8: 0 | H8: 0 | I8: 0 | J8: 0 | K8: 0 | L8: =B8*Datos!$B$31+C8*Datos!$B$32+D8*Datos!$B$33+E8*Datos!$B$34+F8*Datos!$B$35+G8*Datos!$B$36+H8*Datos!$B$37+I8*Datos!$B$38+J8*Datos!$B$39+K8*Datos!$B$40 | M8: =B8*Datos!$C$31+C8*Datos!$C$32+D8*Datos!$C$33+E8*Datos!$C$34+F8*Datos!$C$35+G8*Datos!$C$36+H8*Datos!$C$37+I8*Datos!$C$38+J8*Datos!$C$39+K8*Datos!$C$40 | N8: =L8+M8
A9: Vestuario hombres (23) | B9: 2 | C9: 1 | D9: 0 | E9: 0 | F9: 1 | G9: 0 | H9: 0 | I9: 0 | J9: 0 | K9: 0 | L9: =B9*Datos!$B$31+C9*Datos!$B$32+D9*Datos!$B$33+E9*Datos!$B$34+F9*Datos!$B$35+G9*Datos!$B$36+H9*Datos!$B$37+I9*Datos!$B$38+J9*Datos!$B$39+K9*Datos!$B$40 | M9: =B9*Datos!$C$31+C9*Datos!$C$32+D9*Datos!$C$33+E9*Datos!$C$34+F9*Datos!$C$35+G9*Datos!$C$36+H9*Datos!$C$37+I9*Datos!$C$38+J9*Datos!$C$39+K9*Datos!$C$40 | N9: =L9+M9 | O9: Leyenda: inodoro + ducha + lavabos
A10: Vestuario mujeres (23) | B10: 2 | C10: 1 | D10: 0 | E10: 0 | F10: 1 | G10: 0 | H10: 0 | I10: 0 | J10: 0 | K10: 0 | L10: =B10*Datos!$B$31+C10*Datos!$B$32+D10*Datos!$B$33+E10*Datos!$B$34+F10*Datos!$B$35+G10*Datos!$B$36+H10*Datos!$B$37+I10*Datos!$B$38+J10*Datos!$B$39+K10*Datos!$B$40 | M10: =B10*Datos!$C$31+C10*Datos!$C$32+D10*Datos!$C$33+E10*Datos!$C$34+F10*Datos!$C$35+G10*Datos!$C$36+H10*Datos!$C$37+I10*Datos!$C$38+J10*Datos!$C$39+K10*Datos!$C$40 | N10: =L10+M10
A11: Barra (4) | B11: 0 | C11: 0 | D11: 0 | E11: 0 | F11: 0 | G11: 0 | H11: 1 | I11: 1 | J11: 0 | K11: 0 | L11: =B11*Datos!$B$31+C11*Datos!$B$32+D11*Datos!$B$33+E11*Datos!$B$34+F11*Datos!$B$35+G11*Datos!$B$36+H11*Datos!$B$37+I11*Datos!$B$38+J11*Datos!$B$39+K11*Datos!$B$40 | M11: =B11*Datos!$C$31+C11*Datos!$C$32+D11*Datos!$C$33+E11*Datos!$C$34+F11*Datos!$C$35+G11*Datos!$C$36+H11*Datos!$C$37+I11*Datos!$C$38+J11*Datos!$C$39+K11*Datos!$C$40 | N11: =L11+M11 | O11: Leyenda: fregadero + lavavajillas
A12: Cocina (15) | B12: 0 | C12: 0 | D12: 0 | E12: 0 | F12: 0 | G12: 0 | H12: 1 | I12: 2 | J12: 0 | K12: 0 | L12: =B12*Datos!$B$31+C12*Datos!$B$32+D12*Datos!$B$33+E12*Datos!$B$34+F12*Datos!$B$35+G12*Datos!$B$36+H12*Datos!$B$37+I12*Datos!$B$38+J12*Datos!$B$39+K12*Datos!$B$40 | M12: =B12*Datos!$C$31+C12*Datos!$C$32+D12*Datos!$C$33+E12*Datos!$C$34+F12*Datos!$C$35+G12*Datos!$C$36+H12*Datos!$C$37+I12*Datos!$C$38+J12*Datos!$C$39+K12*Datos!$C$40 | N12: =L12+M12 | O12: Leyenda: 2 lavavajillas + fregadero
A13: Cuarto frío (17) | B13: 0 | C13: 0 | D13: 0 | E13: 0 | F13: 0 | G13: 0 | H13: 1 | I13: 0 | J13: 0 | K13: 0 | L13: =B13*Datos!$B$31+C13*Datos!$B$32+D13*Datos!$B$33+E13*Datos!$B$34+F13*Datos!$B$35+G13*Datos!$B$36+H13*Datos!$B$37+I13*Datos!$B$38+J13*Datos!$B$39+K13*Datos!$B$40 | M13: =B13*Datos!$C$31+C13*Datos!$C$32+D13*Datos!$C$33+E13*Datos!$C$34+F13*Datos!$C$35+G13*Datos!$C$36+H13*Datos!$C$37+I13*Datos!$C$38+J13*Datos!$C$39+K13*Datos!$C$40 | N13: =L13+M13 | O13: Leyenda: fregadero
A14: Cuarto de basuras (19) | B14: 0 | C14: 0 | D14: 0 | E14: 0 | F14: 0 | G14: 0 | H14: 0 | I14: 0 | J14: 0 | K14: 1 | L14: =B14*Datos!$B$31+C14*Datos!$B$32+D14*Datos!$B$33+E14*Datos!$B$34+F14*Datos!$B$35+G14*Datos!$B$36+H14*Datos!$B$37+I14*Datos!$B$38+J14*Datos!$B$39+K14*Datos!$B$40 | M14: =B14*Datos!$C$31+C14*Datos!$C$32+D14*Datos!$C$33+E14*Datos!$C$34+F14*Datos!$C$35+G14*Datos!$C$36+H14*Datos!$C$37+I14*Datos!$C$38+J14*Datos!$C$39+K14*Datos!$C$40 | N14: =L14+M14 | O14: HIPÓTESIS: grifo de limpieza (no dibujado)
A15: Garaje sótano | B15: 0 | C15: 0 | D15: 0 | E15: 0 | F15: 0 | G15: 0 | H15: 0 | I15: 0 | J15: 0 | K15: 1 | L15: =B15*Datos!$B$31+C15*Datos!$B$32+D15*Datos!$B$33+E15*Datos!$B$34+F15*Datos!$B$35+G15*Datos!$B$36+H15*Datos!$B$37+I15*Datos!$B$38+J15*Datos!$B$39+K15*Datos!$B$40 | M15: =B15*Datos!$C$31+C15*Datos!$C$32+D15*Datos!$C$33+E15*Datos!$C$34+F15*Datos!$C$35+G15*Datos!$C$36+H15*Datos!$C$37+I15*Datos!$C$38+J15*Datos!$C$39+K15*Datos!$C$40 | N15: =L15+M15 | O15: HIPÓTESIS: grifo de limpieza (cond. 21: recogida de aguas en sótano)

Sheet Plantas
A1: Inventario por planta, caudales y simultaneidad (UNE 149201)
A3: Planta | B3: Nº | C3: Habitación estándar | D3: Habitación adaptada | E3: Oficio de planta (21) | F3: Aseo público hombres (8) | G3: Aseo público mujeres (8) | H3: Vestuario hombres (23) | I3: Vestuario mujeres (23) | J3: Barra (4) | K3: Cocina (15) | L3: Cuarto frío (17) | M3: Cuarto de basuras (19) | N3: Garaje sótano | O3: Cota solera (m) | P3: Cota grifo (m) | Q3: Qt AF (l/s) | R3: Qt ACS (l/s) | S3: Qt AF+ACS (l/s) | T3: Qc AF planta (l/s) | U3: Qc ACS planta (l/s) | V3: Qt AF acumulado desde cubierta | W3: Qc AF acumulado (montante) (l/s)
A4: Sótano | B4: -1 | C4: 0 | D4: 0 | E4: 0 | F4: 0 | G4: 0 | H4: 0 | I4: 0 | J4: 0 | K4: 0 | L4: 0 | M4: 0 | N4: 1 | O4: =Datos!$B$16 | P4: =O4+Datos!$B$15 | Q4: =C4*Locales!$L$4+D4*Locales!$L$5+E4*Locales!$L$6+F4*Locales!$L$7+G4*Locales!$L$8+H4*Locales!$L$9+I4*Locales!$L$10+J4*Locales!$L$11+K4*Locales!$L$12+L4*Locales!$L$13+M4*Locales!$L$14+N4*Locales!$L$15 | R4: =C4*Locales!$M$4+D4*Locales!$M$5+E4*Locales!$M$6+F4*Locales!$M$7+G4*Locales!$M$8+H4*Locales!$M$9+I4*Locales!$M$10+J4*Locales!$M$11+K4*Locales!$M$12+L4*Locales!$M$13+M4*Locales!$M$14+N4*Locales!$M$15 | S4: =Q4+R4 | T4: =IF(Q4<=0,0,MIN(Q4,IF(Q4<=20,Datos!$B$25*Q4^Datos!$C$25+Datos!$D$25,Datos!$B$26*Q4^Datos!$C$26+Datos!$D$26))) | U4: =IF(R4<=0,0,MIN(R4,IF(R4<=20,Datos!$B$25*R4^Datos!$C$25+Datos!$D$25,Datos!$B$26*R4^Datos!$C$26+Datos!$D$26))) | V4: =SUM(Q4:Q$16) | W4: =IF(V4<=0,0,MIN(V4,IF(V4<=20,Datos!$B$25*V4^Datos!$C$25+Datos!$D$25,Datos!$B$26*V4^Datos!$C$26+Datos!$D$26)))
A5: Planta baja | B5: 0 | C5: 5 | D5: 2 | E5: 1 | F5: 1 | G5: 1 | H5: 1 | I5: 1 | J5: 1 | K5: 1 | L5: 1 | M5: 1 | N5: 0 | O5: =Datos!$B$12 | P5: =O5+Datos!$B$15 | Q5: =C5*Locales!$L$4+D5*Locales!$L$5+E5*Locales!$L$6+F5*Locales!$L$7+G5*Locales!$L$8+H5*Locales!$L$9+I5*Locales!$L$10+J5*Locales!$L$11+K5*Locales!$L$12+L5*Locales!$L$13+M5*Locales!$L$14+N5*Locales!$L$15 | R5: =C5*Locales!$M$4+D5*Locales!$M$5+E5*Locales!$M$6+F5*Locales!$M$7+G5*Locales!$M$8+H5*Locales!$M$9+I5*Locales!$M$10+J5*Locales!$M$11+K5*Locales!$M$12+L5*Locales!$M$13+M5*Locales!$M$14+N5*Locales!$M$15 | S5: =Q5+R5 | T5: =IF(Q5<=0,0,MIN(Q5,IF(Q5<=20,Datos!$B$25*Q5^Datos!$C$25+Datos!$D$25,Datos!$B$26*Q5^Datos!$C$26+Datos!$D$26))) | U5: =IF(R5<=0,0,MIN(R5,IF(R5<=20,Datos!$B$25*R5^Datos!$C$25+Datos!$D$25,Datos!$B$26*R5^Datos!$C$26+Datos!$D$26))) | V5: =SUM(Q5:Q$16) | W5: =IF(V5<=0,0,MIN(V5,IF(V5<=20,Datos!$B$25*V5^Datos!$C$25+Datos!$D$25,Datos!$B$26*V5^Datos!$C$26+Datos!$D$26)))
A6: Planta 1 | B6: 1 | C6: 24 | D6: 2 | E6: 1 | F6: 0 | G6: 0 | H6: 0 | I6: 0 | J6: 0 | K6: 0 | L6: 0 | M6: 0 | N6: 0 | O6: =Datos!$B$12+Datos!$B$13+(B6-1)*Datos!$B$14 | P6: =O6+Datos!$B$15 | Q6: =C6*Locales!$L$4+D6*Locales!$L$5+E6*Locales!$L$6+F6*Locales!$L$7+G6*Locales!$L$8+H6*Locales!$L$9+I6*Locales!$L$10+J6*Locales!$L$11+K6*Locales!$L$12+L6*Locales!$L$13+M6*Locales!$L$14+N6*Locales!$L$15 | R6: =C6*Locales!$M$4+D6*Locales!$M$5+E6*Locales!$M$6+F6*Locales!$M$7+G6*Locales!$M$8+H6*Locales!$M$9+I6*Locales!$M$10+J6*Locales!$M$11+K6*Locales!$M$12+L6*Locales!$M$13+M6*Locales!$M$14+N6*Locales!$M$15 | S6: =Q6+R6 | T6: =IF(Q6<=0,0,MIN(Q6,IF(Q6<=20,Datos!$B$25*Q6^Datos!$C$25+Datos!$D$25,Datos!$B$26*Q6^Datos!$C$26+Datos!$D$26))) | U6: =IF(R6<=0,0,MIN(R6,IF(R6<=20,Datos!$B$25*R6^Datos!$C$25+Datos!$D$25,Datos!$B$26*R6^Datos!$C$26+Datos!$D$26))) | V6: =SUM(Q6:Q$16) | W6: =IF(V6<=0,0,MIN(V6,IF(V6<=20,Datos!$B$25*V6^Datos!$C$25+Datos!$D$25,Datos!$B$26*V6^Datos!$C$26+Datos!$D$26)))
A7: Planta 2 | B7: 2 | C7: 24 | D7: 2 | E7: 1 | F7: 0 | G7: 0 | H7: 0 | I7: 0 | J7: 0 | K7: 0 | L7: 0 | M7: 0 | N7: 0 | O7: =Datos!$B$12+Datos!$B$13+(B7-1)*Datos!$B$14 | P7: =O7+Datos!$B$15 | Q7: =C7*Locales!$L$4+D7*Locales!$L$5+E7*Locales!$L$6+F7*Locales!$L$7+G7*Locales!$L$8+H7*Locales!$L$9+I7*Locales!$L$10+J7*Locales!$L$11+K7*Locales!$L$12+L7*Locales!$L$13+M7*Locales!$L$14+N7*Locales!$L$15 | R7: =C7*Locales!$M$4+D7*Locales!$M$5+E7*Locales!$M$6+F7*Locales!$M$7+G7*Locales!$M$8+H7*Locales!$M$9+I7*Locales!$M$10+J7*Locales!$M$11+K7*Locales!$M$12+L7*Locales!$M$13+M7*Locales!$M$14+N7*Locales!$M$15 | S7: =Q7+R7 | T7: =IF(Q7<=0,0,MIN(Q7,IF(Q7<=20,Datos!$B$25*Q7^Datos!$C$25+Datos!$D$25,Datos!$B$26*Q7^Datos!$C$26+Datos!$D$26))) | U7: =IF(R7<=0,0,MIN(R7,IF(R7<=20,Datos!$B$25*R7^Datos!$C$25+Datos!$D$25,Datos!$B$26*R7^Datos!$C$26+Datos!$D$26))) | V7: =SUM(Q7:Q$16) | W7: =IF(V7<=0,0,MIN(V7,IF(V7<=20,Datos!$B$25*V7^Datos!$C$25+Datos!$D$25,Datos!$B$26*V7^Datos!$C$26+Datos!$D$26)))
A8: Planta 3 | B8: 3 | C8: 24 | D8: 2 | E8: 1 | F8: 0 | G8: 0 | H8: 0 | I8: 0 | J8: 0 | K8: 0 | L8: 0 | M8: 0 | N8: 0 | O8: =Datos!$B$12+Datos!$B$13+(B8-1)*Datos!$B$14 | P8: =O8+Datos!$B$15 | Q8: =C8*Locales!$L$4+D8*Locales!$L$5+E8*Locales!$L$6+F8*Locales!$L$7+G8*Locales!$L$8+H8*Locales!$L$9+I8*Locales!$L$10+J8*Locales!$L$11+K8*Locales!$L$12+L8*Locales!$L$13+M8*Locales!$L$14+N8*Locales!$L$15 | R8: =C8*Locales!$M$4+D8*Locales!$M$5+E8*Locales!$M$6+F8*Locales!$M$7+G8*Locales!$M$8+H8*Locales!$M$9+I8*Locales!$M$10+J8*Locales!$M$11+K8*Locales!$M$12+L8*Locales!$M$13+M8*Locales!$M$14+N8*Locales!$M$15 | S8: =Q8+R8 | T8: =IF(Q8<=0,0,MIN(Q8,IF(Q8<=20,Datos!$B$25*Q8^Datos!$C$25+Datos!$D$25,Datos!$B$26*Q8^Datos!$C$26+Datos!$D$26))) | U8: =IF(R8<=0,0,MIN(R8,IF(R8<=20,Datos!$B$25*R8^Datos!$C$25+Datos!$D$25,Datos!$B$26*R8^Datos!$C$26+Datos!$D$26))) | V8: =SUM(Q8:Q$16) | W8: =IF(V8<=0,0,MIN(V8,IF(V8<=20,Datos!$B$25*V8^Datos!$C$25+Datos!$D$25,Datos!$B$26*V8^Datos!$C$26+Datos!$D$26)))
A9: Planta 4 | B9: 4 | C9: 24 | D9: 2 | E9: 1 | F9: 0 | G9: 0 | H9: 0 | I9: 0 | J9: 0 | K9: 0 | L9: 0 | M9: 0 | N9: 0 | O9: =Datos!$B$12+Datos!$B$13+(B9-1)*Datos!$B$14 | P9: =O9+Datos!$B$15 | Q9: =C9*Locales!$L$4+D9*Locales!$L$5+E9*Locales!$L$6+F9*Locales!$L$7+G9*Locales!$L$8+H9*Locales!$L$9+I9*Locales!$L$10+J9*Locales!$L$11+K9*Locales!$L$12+L9*Locales!$L$13+M9*Locales!$L$14+N9*Locales!$L$15 | R9: =C9*Locales!$M$4+D9*Locales!$M$5+E9*Locales!$M$6+F9*Locales!$M$7+G9*Locales!$M$8+H9*Locales!$M$9+I9*Locales!$M$10+J9*Locales!$M$11+K9*Locales!$M$12+L9*Locales!$M$13+M9*Locales!$M$14+N9*Locales!$M$15 | S9: =Q9+R9 | T9: =IF(Q9<=0,0,MIN(Q9,IF(Q9<=20,Datos!$B$25*Q9^Datos!$C$25+Datos!$D$25,Datos!$B$26*Q9^Datos!$C$26+Datos!$D$26))) | U9: =IF(R9<=0,0,MIN(R9,IF(R9<=20,Datos!$B$25*R9^Datos!$C$25+Datos!$D$25,Datos!$B$26*R9^Datos!$C$26+Datos!$D$26))) | V9: =SUM(Q9:Q$16) | W9: =IF(V9<=0,0,MIN(V9,IF(V9<=20,Datos!$B$25*V9^Datos!$C$25+Datos!$D$25,Datos!$B$26*V9^Datos!$C$26+Datos!$D$26)))
A10: Planta 5 | B10: 5 | C10: 24 | D10: 2 | E10: 1 | F10: 0 | G10: 0 | H10: 0 | I10: 0 | J10: 0 | K10: 0 | L10: 0 | M10: 0 | N10: 0 | O10: =Datos!$B$12+Datos!$B$13+(B10-1)*Datos!$B$14 | P10: =O10+Datos!$B$15 | Q10: =C10*Locales!$L$4+D10*Locales!$L$5+E10*Locales!$L$6+F10*Locales!$L$7+G10*Locales!$L$8+H10*Locales!$L$9+I10*Locales!$L$10+J10*Locales!$L$11+K10*Locales!$L$12+L10*Locales!$L$13+M10*Locales!$L$14+N10*Locales!$L$15 | R10: =C10*Locales!$M$4+D10*Locales!$M$5+E10*Locales!$M$6+F10*Locales!$M$7+G10*Locales!$M$8+H10*Locales!$M$9+I10*Locales!$M$10+J10*Locales!$M$11+K10*Locales!$M$12+L10*Locales!$M$13+M10*Locales!$M$14+N10*Locales!$M$15 | S10: =Q10+R10 | T10: =IF(Q10<=0,0,MIN(Q10,IF(Q10<=20,Datos!$B$25*Q10^Datos!$C$25+Datos!$D$25,Datos!$B$26*Q10^Datos!$C$26+Datos!$D$26))) | U10: =IF(R10<=0,0,MIN(R10,IF(R10<=20,Datos!$B$25*R10^Datos!$C$25+Datos!$D$25,Datos!$B$26*R10^Datos!$C$26+Datos!$D$26))) | V10: =SUM(Q10:Q$16) | W10: =IF(V10<=0,0,MIN(V10,IF(V10<=20,Datos!$B$25*V10^Datos!$C$25+Datos!$D$25,Datos!$B$26*V10^Datos!$C$26+Datos!$D$26)))
A11: Planta 6 | B11: 6 | C11: 24 | D11: 2 | E11: 1 | F11: 0 | G11: 0 | H11: 0 | I11: 0 | J11: 0 | K11: 0 | L11: 0 | M11: 0 | N11: 0 | O11: =Datos!$B$12+Datos!$B$13+(B11-1)*Datos!$B$14 | P11: =O11+Datos!$B$15 | Q11: =C11*Locales!$L$4+D11*Locales!$L$5+E11*Locales!$L$6+F11*Locales!$L$7+G11*Locales!$L$8+H11*Locales!$L$9+I11*Locales!$L$10+J11*Locales!$L$11+K11*Locales!$L$12+L11*Locales!$L$13+M11*Locales!$L$14+N11*Locales!$L$15 | R11: =C11*Locales!$M$4+D11*Locales!$M$5+E11*Locales!$M$6+F11*Locales!$M$7+G11*Locales!$M$8+H11*Locales!$M$9+I11*Locales!$M$10+J11*Locales!$M$11+K11*Locales!$M$12+L11*Locales!$M$13+M11*Locales!$M$14+N11*Locales!$M$15 | S11: =Q11+R11 | T11: =IF(Q11<=0,0,MIN(Q11,IF(Q11<=20,Datos!$B$25*Q11^Datos!$C$25+Datos!$D$25,Datos!$B$26*Q11^Datos!$C$26+Datos!$D$26))) | U11: =IF(R11<=0,0,MIN(R11,IF(R11<=20,Datos!$B$25*R11^Datos!$C$25+Datos!$D$25,Datos!$B$26*R11^Datos!$C$26+Datos!$D$26))) | V11: =SUM(Q11:Q$16) | W11: =IF(V11<=0,0,MIN(V11,IF(V11<=20,Datos!$B$25*V11^Datos!$C$25+Datos!$D$25,Datos!$B$26*V11^Datos!$C$26+Datos!$D$26)))
A12: Planta 7 | B12: 7 | C12: 24 | D12: 2 | E12: 1 | F12: 0 | G12: 0 | H12: 0 | I12: 0 | J12: 0 | K12: 0 | L12: 0 | M12: 0 | N12: 0 | O12: =Datos!$B$12+Datos!$B$13+(B12-1)*Datos!$B$14 | P12: =O12+Datos!$B$15 | Q12: =C12*Locales!$L$4+D12*Locales!$L$5+E12*Locales!$L$6+F12*Locales!$L$7+G12*Locales!$L$8+H12*Locales!$L$9+I12*Locales!$L$10+J12*Locales!$L$11+K12*Locales!$L$12+L12*Locales!$L$13+M12*Locales!$L$14+N12*Locales!$L$15 | R12: =C12*Locales!$M$4+D12*Locales!$M$5+E12*Locales!$M$6+F12*Locales!$M$7+G12*Locales!$M$8+H12*Locales!$M$9+I12*Locales!$M$10+J12*Locales!$M$11+K12*Locales!$M$12+L12*Locales!$M$13+M12*Locales!$M$14+N12*Locales!$M$15 | S12: =Q12+R12 | T12: =IF(Q12<=0,0,MIN(Q12,IF(Q12<=20,Datos!$B$25*Q12^Datos!$C$25+Datos!$D$25,Datos!$B$26*Q12^Datos!$C$26+Datos!$D$26))) | U12: =IF(R12<=0,0,MIN(R12,IF(R12<=20,Datos!$B$25*R12^Datos!$C$25+Datos!$D$25,Datos!$B$26*R12^Datos!$C$26+Datos!$D$26))) | V12: =SUM(Q12:Q$16) | W12: =IF(V12<=0,0,MIN(V12,IF(V12<=20,Datos!$B$25*V12^Datos!$C$25+Datos!$D$25,Datos!$B$26*V12^Datos!$C$26+Datos!$D$26)))
A13: Planta 8 | B13: 8 | C13: 24 | D13: 2 | E13: 1 | F13: 0 | G13: 0 | H13: 0 | I13: 0 | J13: 0 | K13: 0 | L13: 0 | M13: 0 | N13: 0 | O13: =Datos!$B$12+Datos!$B$13+(B13-1)*Datos!$B$14 | P13: =O13+Datos!$B$15 | Q13: =C13*Locales!$L$4+D13*Locales!$L$5+E13*Locales!$L$6+F13*Locales!$L$7+G13*Locales!$L$8+H13*Locales!$L$9+I13*Locales!$L$10+J13*Locales!$L$11+K13*Locales!$L$12+L13*Locales!$L$13+M13*Locales!$L$14+N13*Locales!$L$15 | R13: =C13*Locales!$M$4+D13*Locales!$M$5+E13*Locales!$M$6+F13*Locales!$M$7+G13*Locales!$M$8+H13*Locales!$M$9+I13*Locales!$M$10+J13*Locales!$M$11+K13*Locales!$M$12+L13*Locales!$M$13+M13*Locales!$M$14+N13*Locales!$M$15 | S13: =Q13+R13 | T13: =IF(Q13<=0,0,MIN(Q13,IF(Q13<=20,Datos!$B$25*Q13^Datos!$C$25+Datos!$D$25,Datos!$B$26*Q13^Datos!$C$26+Datos!$D$26))) | U13: =IF(R13<=0,0,MIN(R13,IF(R13<=20,Datos!$B$25*R13^Datos!$C$25+Datos!$D$25,Datos!$B$26*R13^Datos!$C$26+Datos!$D$26))) | V13: =SUM(Q13:Q$16) | W13: =IF(V13<=0,0,MIN(V13,IF(V13<=20,Datos!$B$25*V13^Datos!$C$25+Datos!$D$25,Datos!$B$26*V13^Datos!$C$26+Datos!$D$26)))
A14: Planta 9 | B14: 9 | C14: 24 | D14: 2 | E14: 1 | F14: 0 | G14: 0 | H14: 0 | I14: 0 | J14: 0 | K14: 0 | L14: 0 | M14: 0 | N14: 0 | O14: =Datos!$B$12+Datos!$B$13+(B14-1)*Datos!$B$14 | P14: =O14+Datos!$B$15 | Q14: =C14*Locales!$L$4+D14*Locales!$L$5+E14*Locales!$L$6+F14*Locales!$L$7+G14*Locales!$L$8+H14*Locales!$L$9+I14*Locales!$L$10+J14*Locales!$L$11+K14*Locales!$L$12+L14*Locales!$L$13+M14*Locales!$L$14+N14*Locales!$L$15 | R14: =C14*Locales!$M$4+D14*Locales!$M$5+E14*Locales!$M$6+F14*Locales!$M$7+G14*Locales!$M$8+H14*Locales!$M$9+I14*Locales!$M$10+J14*Locales!$M$11+K14*Locales!$M$12+L14*Locales!$M$13+M14*Locales!$M$14+N14*Locales!$M$15 | S14: =Q14+R14 | T14: =IF(Q14<=0,0,MIN(Q14,IF(Q14<=20,Datos!$B$25*Q14^Datos!$C$25+Datos!$D$25,Datos!$B$26*Q14^Datos!$C$26+Datos!$D$26))) | U14: =IF(R14<=0,0,MIN(R14,IF(R14<=20,Datos!$B$25*R14^Datos!$C$25+Datos!$D$25,Datos!$B$26*R14^Datos!$C$26+Datos!$D$26))) | V14: =SUM(Q14:Q$16) | W14: =IF(V14<=0,0,MIN(V14,IF(V14<=20,Datos!$B$25*V14^Datos!$C$25+Datos!$D$25,Datos!$B$26*V14^Datos!$C$26+Datos!$D$26)))
A15: Planta 10 | B15: 10 | C15: 24 | D15: 2 | E15: 1 | F15: 0 | G15: 0 | H15: 0 | I15: 0 | J15: 0 | K15: 0 | L15: 0 | M15: 0 | N15: 0 | O15: =Datos!$B$12+Datos!$B$13+(B15-1)*Datos!$B$14 | P15: =O15+Datos!$B$15 | Q15: =C15*Locales!$L$4+D15*Locales!$L$5+E15*Locales!$L$6+F15*Locales!$L$7+G15*Locales!$L$8+H15*Locales!$L$9+I15*Locales!$L$10+J15*Locales!$L$11+K15*Locales!$L$12+L15*Locales!$L$13+M15*Locales!$L$14+N15*Locales!$L$15 | R15: =C15*Locales!$M$4+D15*Locales!$M$5+E15*Locales!$M$6+F15*Locales!$M$7+G15*Locales!$M$8+H15*Locales!$M$9+I15*Locales!$M$10+J15*Locales!$M$11+K15*Locales!$M$12+L15*Locales!$M$13+M15*Locales!$M$14+N15*Locales!$M$15 | S15: =Q15+R15 | T15: =IF(Q15<=0,0,MIN(Q15,IF(Q15<=20,Datos!$B$25*Q15^Datos!$C$25+Datos!$D$25,Datos!$B$26*Q15^Datos!$C$26+Datos!$D$26))) | U15: =IF(R15<=0,0,MIN(R15,IF(R15<=20,Datos!$B$25*R15^Datos!$C$25+Datos!$D$25,Datos!$B$26*R15^Datos!$C$26+Datos!$D$26))) | V15: =SUM(Q15:Q$16) | W15: =IF(V15<=0,0,MIN(V15,IF(V15<=20,Datos!$B$25*V15^Datos!$C$25+Datos!$D$25,Datos!$B$26*V15^Datos!$C$26+Datos!$D$26)))
A16: Planta 11 | B16: 11 | C16: 24 | D16: 2 | E16: 1 | F16: 0 | G16: 0 | H16: 0 | I16: 0 | J16: 0 | K16: 0 | L16: 0 | M16: 0 | N16: 0 | O16: =Datos!$B$12+Datos!$B$13+(B16-1)*Datos!$B$14 | P16: =O16+Datos!$B$15 | Q16: =C16*Locales!$L$4+D16*Locales!$L$5+E16*Locales!$L$6+F16*Locales!$L$7+G16*Locales!$L$8+H16*Locales!$L$9+I16*Locales!$L$10+J16*Locales!$L$11+K16*Locales!$L$12+L16*Locales!$L$13+M16*Locales!$L$14+N16*Locales!$L$15 | R16: =C16*Locales!$M$4+D16*Locales!$M$5+E16*Locales!$M$6+F16*Locales!$M$7+G16*Locales!$M$8+H16*Locales!$M$9+I16*Locales!$M$10+J16*Locales!$M$11+K16*Locales!$M$12+L16*Locales!$M$13+M16*Locales!$M$14+N16*Locales!$M$15 | S16: =Q16+R16 | T16: =IF(Q16<=0,0,MIN(Q16,IF(Q16<=20,Datos!$B$25*Q16^Datos!$C$25+Datos!$D$25,Datos!$B$26*Q16^Datos!$C$26+Datos!$D$26))) | U16: =IF(R16<=0,0,MIN(R16,IF(R16<=20,Datos!$B$25*R16^Datos!$C$25+Datos!$D$25,Datos!$B$26*R16^Datos!$C$26+Datos!$D$26))) | V16: =SUM(Q16:Q$16) | W16: =IF(V16<=0,0,MIN(V16,IF(V16<=20,Datos!$B$25*V16^Datos!$C$25+Datos!$D$25,Datos!$B$26*V16^Datos!$C$26+Datos!$D$26)))
A17: TOTAL EDIFICIO | Q17: =SUM(Q4:Q16) | R17: =SUM(R4:R16) | S17: =SUM(S4:S16) | T17: =IF(Q17<=0,0,MIN(Q17,IF(Q17<=20,Datos!$B$25*Q17^Datos!$C$25+Datos!$D$25,Datos!$B$26*Q17^Datos!$C$26+Datos!$D$26))) | U17: =IF(R17<=0,0,MIN(R17,IF(R17<=20,Datos!$B$25*R17^Datos!$C$25+Datos!$D$25,Datos!$B$26*R17^Datos!$C$26+Datos!$D$26)))
A18: Qc instalación general común (AF + alimentación producción ACS): | S18: =IF(S17<=0,0,MIN(S17,IF(S17<=20,Datos!$B$25*S17^Datos!$C$25+Datos!$D$25,Datos!$B$26*S17^Datos!$C$26+Datos!$D$26)))
A19: Nota: la simultaneidad se aplica al caudal instalado acumulado de cada tramo (UNE 149201). Qc nunca supera Qt.

Sheet Escalones
A1: Predimensionado: plantas abastecibles en directo con la presión de red
A2: P grifo = P red − (z grifo − z calzada) − Σhm − j·L·fLeq (Procedimiento diseño UPV, paso 3). Valores de j, Σhm y longitudes = estimación previa al trazado.
A3: NOTA: este es el PREDIMENSIONADO inicial (paso 3 del procedimiento, con j y Σhm estimadas). El cálculo definitivo con el trazado real está en la hoja Recorridos: directo PB–P7, bombeo P8–P11.
A4: Dato | B4: Valor | C4: Unidad | D4: Nota
A5: Pendiente hidráulica de diseño j | B5: 40 | C5: mm/m | D5: HIPÓTESIS: rango 15-150 mm/m
A6: Σ pérdidas singulares (llave, filtro, contador, retención, llaves) | B6: 5 | C6: mca | D6: HIPÓTESIS: se recalcula con K reales
A7: L acometida → patinillo (incl. bajada a sótano) | B7: 20 | C7: m | D7: HIPÓTESIS: acometida por fachada OESTE, núcleo escalera 1 (medir en plano)
A8: L horizontal planta: patinillo → habitación más alejada | B8: 47 | C8: m | D8: Medido en DWG: núcleo x≈4 m a hab. extremo x≈51 m
A9: L interior habitación hasta aparato DSF | B9: 6 | C9: m | D9: HIPÓTESIS
A11: Planta | B11: Cota grifo (m) | C11: L real (m) | D11: hf = j·L·fLeq (mca) | E11: Σhm (mca) | F11: P grifo DSF (mca) | G11: ¿Directo? (≥10 mca)
A12: =Plantas!A5 | B12: =Plantas!P5 | C12: =$B$7+(B12-Datos!$B$16)+$B$8+$B$9 | D12: =$B$5/1000*C12*Datos!$B$17 | E12: =$B$6 | F12: =Datos!$B$7-(B12-Datos!$B$11)-D12-E12 | G12: =IF(F12>=Datos!$B$18,"SÍ","NO → bombeo")
A13: =Plantas!A6 | B13: =Plantas!P6 | C13: =$B$7+(B13-Datos!$B$16)+$B$8+$B$9 | D13: =$B$5/1000*C13*Datos!$B$17 | E13: =$B$6 | F13: =Datos!$B$7-(B13-Datos!$B$11)-D13-E13 | G13: =IF(F13>=Datos!$B$18,"SÍ","NO → bombeo")
A14: =Plantas!A7 | B14: =Plantas!P7 | C14: =$B$7+(B14-Datos!$B$16)+$B$8+$B$9 | D14: =$B$5/1000*C14*Datos!$B$17 | E14: =$B$6 | F14: =Datos!$B$7-(B14-Datos!$B$11)-D14-E14 | G14: =IF(F14>=Datos!$B$18,"SÍ","NO → bombeo")
A15: =Plantas!A8 | B15: =Plantas!P8 | C15: =$B$7+(B15-Datos!$B$16)+$B$8+$B$9 | D15: =$B$5/1000*C15*Datos!$B$17 | E15: =$B$6 | F15: =Datos!$B$7-(B15-Datos!$B$11)-D15-E15 | G15: =IF(F15>=Datos!$B$18,"SÍ","NO → bombeo")
A16: =Plantas!A9 | B16: =Plantas!P9 | C16: =$B$7+(B16-Datos!$B$16)+$B$8+$B$9 | D16: =$B$5/1000*C16*Datos!$B$17 | E16: =$B$6 | F16: =Datos!$B$7-(B16-Datos!$B$11)-D16-E16 | G16: =IF(F16>=Datos!$B$18,"SÍ","NO → bombeo")
A17: =Plantas!A10 | B17: =Plantas!P10 | C17: =$B$7+(B17-Datos!$B$16)+$B$8+$B$9 | D17: =$B$5/1000*C17*Datos!$B$17 | E17: =$B$6 | F17: =Datos!$B$7-(B17-Datos!$B$11)-D17-E17 | G17: =IF(F17>=Datos!$B$18,"SÍ","NO → bombeo")
A18: =Plantas!A11 | B18: =Plantas!P11 | C18: =$B$7+(B18-Datos!$B$16)+$B$8+$B$9 | D18: =$B$5/1000*C18*Datos!$B$17 | E18: =$B$6 | F18: =Datos!$B$7-(B18-Datos!$B$11)-D18-E18 | G18: =IF(F18>=Datos!$B$18,"SÍ","NO → bombeo")
A19: =Plantas!A12 | B19: =Plantas!P12 | C19: =$B$7+(B19-Datos!$B$16)+$B$8+$B$9 | D19: =$B$5/1000*C19*Datos!$B$17 | E19: =$B$6 | F19: =Datos!$B$7-(B19-Datos!$B$11)-D19-E19 | G19: =IF(F19>=Datos!$B$18,"SÍ","NO → bombeo")
A20: =Plantas!A13 | B20: =Plantas!P13 | C20: =$B$7+(B20-Datos!$B$16)+$B$8+$B$9 | D20: =$B$5/1000*C20*Datos!$B$17 | E20: =$B$6 | F20: =Datos!$B$7-(B20-Datos!$B$11)-D20-E20 | G20: =IF(F20>=Datos!$B$18,"SÍ","NO → bombeo")
A21: =Plantas!A14 | B21: =Plantas!P14 | C21: =$B$7+(B21-Datos!$B$16)+$B$8+$B$9 | D21: =$B$5/1000*C21*Datos!$B$17 | E21: =$B$6 | F21: =Datos!$B$7-(B21-Datos!$B$11)-D21-E21 | G21: =IF(F21>=Datos!$B$18,"SÍ","NO → bombeo")
A22: =Plantas!A15 | B22: =Plantas!P15 | C22: =$B$7+(B22-Datos!$B$16)+$B$8+$B$9 | D22: =$B$5/1000*C22*Datos!$B$17 | E22: =$B$6 | F22: =Datos!$B$7-(B22-Datos!$B$11)-D22-E22 | G22: =IF(F22>=Datos!$B$18,"SÍ","NO → bombeo")
A23: =Plantas!A16 | B23: =Plantas!P16 | C23: =$B$7+(B23-Datos!$B$16)+$B$8+$B$9 | D23: =$B$5/1000*C23*Datos!$B$17 | E23: =$B$6 | F23: =Datos!$B$7-(B23-Datos!$B$11)-D23-E23 | G23: =IF(F23>=Datos!$B$18,"SÍ","NO → bombeo")
A25: Plantas en directo (incluida PB): | B25: =COUNTIF(G12:G23,"SÍ")
A26: Plantas con bombeo: | B26: =COUNTIF(G12:G23,"NO*")
A28: Comprobación nº de plantas por estación con BVF (Procedimiento paso 3): Pmin + Δp calderín + Δz·NP < 50 mca
A29: NP máximo con BVF: | B29: =INT((Datos!$B$19-Datos!$B$18-Datos!$B$20)/Datos!$B$14)
A30: Límite enunciado (cond. 28): BVF ≤ 6 alturas · BVV ≤ 10 alturas por estación

Sheet Tubos
A1: Diámetros comerciales (interior). Multicapa PE-RT/Al/PE-RT PN10 a 70 ºC · PE100 SDR11 PN16 · valvulería por DN
A2: Comprobar las medidas con el catálogo comercial concreto que elijáis (multicapa: serie habitual 16…90 mm).
A3: Serie | B3: Designación | C3: Di (mm)
A4: MC | B4: MC 16x2 | C4: 12
A5: MC | B5: MC 20x2 | C5: 16
A6: MC | B6: MC 26x3 | C6: 20
A7: MC | B7: MC 32x3 | C7: 26
A8: MC | B8: MC 40x3.5 | C8: 33
A9: MC | B9: MC 50x4 | C9: 42
A10: MC | B10: MC 63x4.5 | C10: 54
A11: MC | B11: MC 75x5 | C11: 65
A12: MC | B12: MC 90x6 | C12: 78
A14: Serie | B14: Designación | C14: Di (mm)
A15: PE | B15: PE 40x3.7 | C15: 32.6
A16: PE | B16: PE 50x4.6 | C16: 40.8
A17: PE | B17: PE 63x5.8 | C17: 51.4
A18: PE | B18: PE 75x6.8 | C18: 61.4
A19: PE | B19: PE 90x8.2 | C19: 73.6
A20: PE | B20: PE 110x10 | C20: 90
A21: PE | B21: PE 125x11.4 | C21: 102.2
A23: Serie | B23: Designación | C23: Di (mm)
A24: VAL | B24: DN15 | C24: 15
A25: VAL | B25: DN20 | C25: 20
A26: VAL | B26: DN25 | C26: 25
A27: VAL | B27: DN32 | C27: 32
A28: VAL | B28: DN40 | C28: 40
A29: VAL | B29: DN50 | C29: 50
A30: VAL | B30: DN65 | C30: 65
A31: VAL | B31: DN80 | C31: 80
A32: VAL | B32: DN100 | C32: 100
A33: VAL | B33: DN125 | C33: 125

Sheet Tramos
A1: Dimensionado de tramos · Qc según UNE 149201 · Darcy-Weisbach (Swamee-Jain) · L cálculo = L real × 1,30
A2: Azul = dato (longitudes medidas en el DWG, nº de locales aguas abajo). Para forzar otro diámetro, cambia la velocidad objetivo (col. L).
A4: ID | B4: Descripción | C4: Circuito | D4: Serie | E4: Hab. estándar aguas abajo | F4: Hab. adaptadas aguas abajo | G4: Oficios aguas abajo | H4: Qt adicional (l/s) | I4: Qt (l/s) | J4: Q aparato mayor (l/s) | K4: Qc (l/s) | L4: v objetivo (m/s) | M4: D teórico (mm) | N4: Designación | O4: Di (mm) | P4: v (m/s) | Q4: L real (m) | R4: L cálculo (m) | S4: Re | T4: f | U4: hf (mca) | V4: ΣK | W4: hm (mca) | X4: hf+hm (mca)
A5: G1 | B5: Acometida: red general (fachada O) → hornacina contador | C5: AF | D5: PE | E5: 0 | F5: 0 | G5: 0 | H5: =Plantas!$S$17 | I5: =IF(C5="AF",E5*Locales!$L$4+F5*Locales!$L$5+G5*Locales!$L$6,E5*Locales!$M$4+F5*Locales!$M$5+G5*Locales!$M$6)+H5 | J5: 0 | K5: =MAX(J5,IF(I5<=0,0,MIN(I5,IF(I5<=20,Datos!$B$25*I5^Datos!$C$25+Datos!$D$25,Datos!$B$26*I5^Datos!$C$26+Datos!$D$26)))) | L5: 1.2 | M5: =SQRT(4*K5/1000/(PI()*L5))*1000 | N5: =IF(D5="MC",INDEX(Tubos!$B$4:$B$12,MIN(COUNTIF(Tubos!$C$4:$C$12,"<"&M5)+1,9)),IF(D5="PE",INDEX(Tubos!$B$15:$B$21,MIN(COUNTIF(Tubos!$C$15:$C$21,"<"&M5)+1,7)),INDEX(Tubos!$B$24:$B$33,MIN(COUNTIF(Tubos!$C$24:$C$33,"<"&M5)+1,10)))) | O5: =IF(D5="MC",INDEX(Tubos!$C$4:$C$12,MIN(COUNTIF(Tubos!$C$4:$C$12,"<"&M5)+1,9)),IF(D5="PE",INDEX(Tubos!$C$15:$C$21,MIN(COUNTIF(Tubos!$C$15:$C$21,"<"&M5)+1,7)),INDEX(Tubos!$C$24:$C$33,MIN(COUNTIF(Tubos!$C$24:$C$33,"<"&M5)+1,10)))) | P5: =K5/1000/(PI()*(O5/1000)^2/4) | Q5: 14 | R5: =Q5*Datos!$B$17 | S5: =P5*O5/1000/IF(C5="AF",Datos!$B$46,Datos!$B$47) | T5: =IF(S5<=0,0,0.25/(LOG10(Datos!$B$48/(3.7*O5/1000)+5.74/S5^0.9))^2) | U5: =IF(R5=0,0,T5*R5/(O5/1000)*P5^2/(2*Datos!$B$45)) | V5: 0.6 | W5: =V5*P5^2/(2*Datos!$B$45) | X5: =U5+W5
A6: E1 | B6: Contador general (hornacina fachada O) | C6: AF | D6: VAL | E6: 0 | F6: 0 | G6: 0 | H6: =Plantas!$S$17 | I6: =IF(C6="AF",E6*Locales!$L$4+F6*Locales!$L$5+G6*Locales!$L$6,E6*Locales!$M$4+F6*Locales!$M$5+G6*Locales!$M$6)+H6 | J6: 0 | K6: =MAX(J6,IF(I6<=0,0,MIN(I6,IF(I6<=20,Datos!$B$25*I6^Datos!$C$25+Datos!$D$25,Datos!$B$26*I6^Datos!$C$26+Datos!$D$26)))) | L6: 1 | M6: =SQRT(4*K6/1000/(PI()*L6))*1000 | N6: =IF(D6="MC",INDEX(Tubos!$B$4:$B$12,MIN(COUNTIF(Tubos!$C$4:$C$12,"<"&M6)+1,9)),IF(D6="PE",INDEX(Tubos!$B$15:$B$21,MIN(COUNTIF(Tubos!$C$15:$C$21,"<"&M6)+1,7)),INDEX(Tubos!$B$24:$B$33,MIN(COUNTIF(Tubos!$C$24:$C$33,"<"&M6)+1,10)))) | O6: =IF(D6="MC",INDEX(Tubos!$C$4:$C$12,MIN(COUNTIF(Tubos!$C$4:$C$12,"<"&M6)+1,9)),IF(D6="PE",INDEX(Tubos!$C$15:$C$21,MIN(COUNTIF(Tubos!$C$15:$C$21,"<"&M6)+1,7)),INDEX(Tubos!$C$24:$C$33,MIN(COUNTIF(Tubos!$C$24:$C$33,"<"&M6)+1,10)))) | P6: =K6/1000/(PI()*(O6/1000)^2/4) | Q6: 0 | R6: =Q6*Datos!$B$17 | S6: =P6*O6/1000/IF(C6="AF",Datos!$B$46,Datos!$B$47) | T6: =IF(S6<=0,0,0.25/(LOG10(Datos!$B$48/(3.7*O6/1000)+5.74/S6^0.9))^2) | U6: =IF(R6=0,0,T6*R6/(O6/1000)*P6^2/(2*Datos!$B$45)) | V6: 10 | W6: =V6*P6^2/(2*Datos!$B$45) | X6: =U6+W6
A7: E2 | B7: Válvula de retención general | C7: AF | D7: VAL | E7: 0 | F7: 0 | G7: 0 | H7: =Plantas!$S$17 | I7: =IF(C7="AF",E7*Locales!$L$4+F7*Locales!$L$5+G7*Locales!$L$6,E7*Locales!$M$4+F7*Locales!$M$5+G7*Locales!$M$6)+H7 | J7: 0 | K7: =MAX(J7,IF(I7<=0,0,MIN(I7,IF(I7<=20,Datos!$B$25*I7^Datos!$C$25+Datos!$D$25,Datos!$B$26*I7^Datos!$C$26+Datos!$D$26)))) | L7: 1 | M7: =SQRT(4*K7/1000/(PI()*L7))*1000 | N7: =IF(D7="MC",INDEX(Tubos!$B$4:$B$12,MIN(COUNTIF(Tubos!$C$4:$C$12,"<"&M7)+1,9)),IF(D7="PE",INDEX(Tubos!$B$15:$B$21,MIN(COUNTIF(Tubos!$C$15:$C$21,"<"&M7)+1,7)),INDEX(Tubos!$B$24:$B$33,MIN(COUNTIF(Tubos!$C$24:$C$33,"<"&M7)+1,10)))) | O7: =IF(D7="MC",INDEX(Tubos!$C$4:$C$12,MIN(COUNTIF(Tubos!$C$4:$C$12,"<"&M7)+1,9)),IF(D7="PE",INDEX(Tubos!$C$15:$C$21,MIN(COUNTIF(Tubos!$C$15:$C$21,"<"&M7)+1,7)),INDEX(Tubos!$C$24:$C$33,MIN(COUNTIF(Tubos!$C$24:$C$33,"<"&M7)+1,10)))) | P7: =K7/1000/(PI()*(O7/1000)^2/4) | Q7: 0 | R7: =Q7*Datos!$B$17 | S7: =P7*O7/1000/IF(C7="AF",Datos!$B$46,Datos!$B$47) | T7: =IF(S7<=0,0,0.25/(LOG10(Datos!$B$48/(3.7*O7/1000)+5.74/S7^0.9))^2) | U7: =IF(R7=0,0,T7*R7/(O7/1000)*P7^2/(2*Datos!$B$45)) | V7: 2.5 | W7: =V7*P7^2/(2*Datos!$B$45) | X7: =U7+W7
A8: E3 | B8: Llaves de aislamiento contador (2 ud) | C8: AF | D8: VAL | E8: 0 | F8: 0 | G8: 0 | H8: =Plantas!$S$17 | I8: =IF(C8="AF",E8*Locales!$L$4+F8*Locales!$L$5+G8*Locales!$L$6,E8*Locales!$M$4+F8*Locales!$M$5+G8*Locales!$M$6)+H8 | J8: 0 | K8: =MAX(J8,IF(I8<=0,0,MIN(I8,IF(I8<=20,Datos!$B$25*I8^Datos!$C$25+Datos!$D$25,Datos!$B$26*I8^Datos!$C$26+Datos!$D$26)))) | L8: 1 | M8: =SQRT(4*K8/1000/(PI()*L8))*1000 | N8: =IF(D8="MC",INDEX(Tubos!$B$4:$B$12,MIN(COUNTIF(Tubos!$C$4:$C$12,"<"&M8)+1,9)),IF(D8="PE",INDEX(Tubos!$B$15:$B$21,MIN(COUNTIF(Tubos!$C$15:$C$21,"<"&M8)+1,7)),INDEX(Tubos!$B$24:$B$33,MIN(COUNTIF(Tubos!$C$24:$C$33,"<"&M8)+1,10)))) | O8: =IF(D8="MC",INDEX(Tubos!$C$4:$C$12,MIN(COUNTIF(Tubos!$C$4:$C$12,"<"&M8)+1,9)),IF(D8="PE",INDEX(Tubos!$C$15:$C$21,MIN(COUNTIF(Tubos!$C$15:$C$21,"<"&M8)+1,7)),INDEX(Tubos!$C$24:$C$33,MIN(COUNTIF(Tubos!$C$24:$C$33,"<"&M8)+1,10)))) | P8: =K8/1000/(PI()*(O8/1000)^2/4) | Q8: 0 | R8: =Q8*Datos!$B$17 | S8: =P8*O8/1000/IF(C8="AF",Datos!$B$46,Datos!$B$47) | T8: =IF(S8<=0,0,0.25/(LOG10(Datos!$B$48/(3.7*O8/1000)+5.74/S8^0.9))^2) | U8: =IF(R8=0,0,T8*R8/(O8/1000)*P8^2/(2*Datos!$B$45)) | V8: 0.6 | W8: =V8*P8^2/(2*Datos!$B$45) | X8: =U8+W8
A9: G2 | B9: Tubo de alimentación: hornacina → cuarto AF sótano (colgado) | C9: AF | D9: PE | E9: 0 | F9: 0 | G9: 0 | H9: =Plantas!$S$17 | I9: =IF(C9="AF",E9*Locales!$L$4+F9*Locales!$L$5+G9*Locales!$L$6,E9*Locales!$M$4+F9*Locales!$M$5+G9*Locales!$M$6)+H9 | J9: 0 | K9: =MAX(J9,IF(I9<=0,0,MIN(I9,IF(I9<=20,Datos!$B$25*I9^Datos!$C$25+Datos!$D$25,Datos!$B$26*I9^Datos!$C$26+Datos!$D$26)))) | L9: 1.2 | M9: =SQRT(4*K9/1000/(PI()*L9))*1000 | N9: =IF(D9="MC",INDEX(Tubos!$B$4:$B$12,MIN(COUNTIF(Tubos!$C$4:$C$12,"<"&M9)+1,9)),IF(D9="PE",INDEX(Tubos!$B$15:$B$21,MIN(COUNTIF(Tubos!$C$15:$C$21,"<"&M9)+1,7)),INDEX(Tubos!$B$24:$B$33,MIN(COUNTIF(Tubos!$C$24:$C$33,"<"&M9)+1,10)))) | O9: =IF(D9="MC",INDEX(Tubos!$C$4:$C$12,MIN(COUNTIF(Tubos!$C$4:$C$12,"<"&M9)+1,9)),IF(D9="PE",INDEX(Tubos!$C$15:$C$21,MIN(COUNTIF(Tubos!$C$15:$C$21,"<"&M9)+1,7)),INDEX(Tubos!$C$24:$C$33,MIN(COUNTIF(Tubos!$C$24:$C$33,"<"&M9)+1,10)))) | P9: =K9/1000/(PI()*(O9/1000)^2/4) | Q9: 14 | R9: =Q9*Datos!$B$17 | S9: =P9*O9/1000/IF(C9="AF",Datos!$B$46,Datos!$B$47) | T9: =IF(S9<=0,0,0.25/(LOG10(Datos!$B$48/(3.7*O9/1000)+5.74/S9^0.9))^2) | U9: =IF(R9=0,0,T9*R9/(O9/1000)*P9^2/(2*Datos!$B$45)) | V9: 0.3 | W9: =V9*P9^2/(2*Datos!$B$45) | X9: =U9+W9
A10: E4 | B10: Filtro general (cuarto AF) | C10: AF | D10: VAL | E10: 0 | F10: 0 | G10: 0 | H10: =Plantas!$S$17 | I10: =IF(C10="AF",E10*Locales!$L$4+F10*Locales!$L$5+G10*Locales!$L$6,E10*Locales!$M$4+F10*Locales!$M$5+G10*Locales!$M$6)+H10 | J10: 0 | K10: =MAX(J10,IF(I10<=0,0,MIN(I10,IF(I10<=20,Datos!$B$25*I10^Datos!$C$25+Datos!$D$25,Datos!$B$26*I10^Datos!$C$26+Datos!$D$26)))) | L10: 1 | M10: =SQRT(4*K10/1000/(PI()*L10))*1000 | N10: =IF(D10="MC",INDEX(Tubos!$B$4:$B$12,MIN(COUNTIF(Tubos!$C$4:$C$12,"<"&M10)+1,9)),IF(D10="PE",INDEX(Tubos!$B$15:$B$21,MIN(COUNTIF(Tubos!$C$15:$C$21,"<"&M10)+1,7)),INDEX(Tubos!$B$24:$B$33,MIN(COUNTIF(Tubos!$C$24:$C$33,"<"&M10)+1,10)))) | O10: =IF(D10="MC",INDEX(Tubos!$C$4:$C$12,MIN(COUNTIF(Tubos!$C$4:$C$12,"<"&M10)+1,9)),IF(D10="PE",INDEX(Tubos!$C$15:$C$21,MIN(COUNTIF(Tubos!$C$15:$C$21,"<"&M10)+1,7)),INDEX(Tubos!$C$24:$C$33,MIN(COUNTIF(Tubos!$C$24:$C$33,"<"&M10)+1,10)))) | P10: =K10/1000/(PI()*(O10/1000)^2/4) | Q10: 0 | R10: =Q10*Datos!$B$17 | S10: =P10*O10/1000/IF(C10="AF",Datos!$B$46,Datos!$B$47) | T10: =IF(S10<=0,0,0.25/(LOG10(Datos!$B$48/(3.7*O10/1000)+5.74/S10^0.9))^2) | U10: =IF(R10=0,0,T10*R10/(O10/1000)*P10^2/(2*Datos!$B$45)) | V10: 5 | W10: =V10*P10^2/(2*Datos!$B$45) | X10: =U10+W10
A11: D0 | B11: Colector directo (cuarto AF) + llave aislamiento | C11: AF | D11: MC | E11: 168 | F11: 14 | G11: 7 | H11: =Plantas!$Q$5+Plantas!$Q$4 | I11: =IF(C11="AF",E11*Locales!$L$4+F11*Locales!$L$5+G11*Locales!$L$6,E11*Locales!$M$4+F11*Locales!$M$5+G11*Locales!$M$6)+H11 | J11: 0 | K11: =MAX(J11,IF(I11<=0,0,MIN(I11,IF(I11<=20,Datos!$B$25*I11^Datos!$C$25+Datos!$D$25,Datos!$B$26*I11^Datos!$C$26+Datos!$D$26)))) | L11: 1 | M11: =SQRT(4*K11/1000/(PI()*L11))*1000 | N11: =IF(D11="MC",INDEX(Tubos!$B$4:$B$12,MIN(COUNTIF(Tubos!$C$4:$C$12,"<"&M11)+1,9)),IF(D11="PE",INDEX(Tubos!$B$15:$B$21,MIN(COUNTIF(Tubos!$C$15:$C$21,"<"&M11)+1,7)),INDEX(Tubos!$B$24:$B$33,MIN(COUNTIF(Tubos!$C$24:$C$33,"<"&M11)+1,10)))) | O11: =IF(D11="MC",INDEX(Tubos!$C$4:$C$12,MIN(COUNTIF(Tubos!$C$4:$C$12,"<"&M11)+1,9)),IF(D11="PE",INDEX(Tubos!$C$15:$C$21,MIN(COUNTIF(Tubos!$C$15:$C$21,"<"&M11)+1,7)),INDEX(Tubos!$C$24:$C$33,MIN(COUNTIF(Tubos!$C$24:$C$33,"<"&M11)+1,10)))) | P11: =K11/1000/(PI()*(O11/1000)^2/4) | Q11: 2 | R11: =Q11*Datos!$B$17 | S11: =P11*O11/1000/IF(C11="AF",Datos!$B$46,Datos!$B$47) | T11: =IF(S11<=0,0,0.25/(LOG10(Datos!$B$48/(3.7*O11/1000)+5.74/S11^0.9))^2) | U11: =IF(R11=0,0,T11*R11/(O11/1000)*P11^2/(2*Datos!$B$45)) | V11: 0.3 | W11: =V11*P11^2/(2*Datos!$B$45) | X11: =U11+W11
A12: DL1 | B12: Directo: cuarto AF → base patinillo O | C12: AF | D12: MC | E12: 84 | F12: 14 | G12: 0 | H12: 0 | I12: =IF(C12="AF",E12*Locales!$L$4+F12*Locales!$L$5+G12*Locales!$L$6,E12*Locales!$M$4+F12*Locales!$M$5+G12*Locales!$M$6)+H12 | J12: 0 | K12: =MAX(J12,IF(I12<=0,0,MIN(I12,IF(I12<=20,Datos!$B$25*I12^Datos!$C$25+Datos!$D$25,Datos!$B$26*I12^Datos!$C$26+Datos!$D$26)))) | L12: 1 | M12: =SQRT(4*K12/1000/(PI()*L12))*1000 | N12: =IF(D12="MC",INDEX(Tubos!$B$4:$B$12,MIN(COUNTIF(Tubos!$C$4:$C$12,"<"&M12)+1,9)),IF(D12="PE",INDEX(Tubos!$B$15:$B$21,MIN(COUNTIF(Tubos!$C$15:$C$21,"<"&M12)+1,7)),INDEX(Tubos!$B$24:$B$33,MIN(COUNTIF(Tubos!$C$24:$C$33,"<"&M12)+1,10)))) | O12: =IF(D12="MC",INDEX(Tubos!$C$4:$C$12,MIN(COUNTIF(Tubos!$C$4:$C$12,"<"&M12)+1,9)),IF(D12="PE",INDEX(Tubos!$C$15:$C$21,MIN(COUNTIF(Tubos!$C$15:$C$21,"<"&M12)+1,7)),INDEX(Tubos!$C$24:$C$33,MIN(COUNTIF(Tubos!$C$24:$C$33,"<"&M12)+1,10)))) | P12: =K12/1000/(PI()*(O12/1000)^2/4) | Q12: 12 | R12: =Q12*Datos!$B$17 | S12: =P12*O12/1000/IF(C12="AF",Datos!$B$46,Datos!$B$47) | T12: =IF(S12<=0,0,0.25/(LOG10(Datos!$B$48/(3.7*O12/1000)+5.74/S12^0.9))^2) | U12: =IF(R12=0,0,T12*R12/(O12/1000)*P12^2/(2*Datos!$B$45)) | V12: 2.8 | W12: =V12*P12^2/(2*Datos!$B$45) | X12: =U12+W12
A13: DR1 | B13: Directo: cuarto AF → base patinillo E | C13: AF | D13: MC | E13: 84 | F13: 0 | G13: 7 | H13: 0 | I13: =IF(C13="AF",E13*Locales!$L$4+F13*Locales!$L$5+G13*Locales!$L$6,E13*Locales!$M$4+F13*Locales!$M$5+G13*Locales!$M$6)+H13 | J13: 0 | K13: =MAX(J13,IF(I13<=0,0,MIN(I13,IF(I13<=20,Datos!$B$25*I13^Datos!$C$25+Datos!$D$25,Datos!$B$26*I13^Datos!$C$26+Datos!$D$26)))) | L13: 1 | M13: =SQRT(4*K13/1000/(PI()*L13))*1000 | N13: =IF(D13="MC",INDEX(Tubos!$B$4:$B$12,MIN(COUNTIF(Tubos!$C$4:$C$12,"<"&M13)+1,9)),IF(D13="PE",INDEX(Tubos!$B$15:$B$21,MIN(COUNTIF(Tubos!$C$15:$C$21,"<"&M13)+1,7)),INDEX(Tubos!$B$24:$B$33,MIN(COUNTIF(Tubos!$C$24:$C$33,"<"&M13)+1,10)))) | O13: =IF(D13="MC",INDEX(Tubos!$C$4:$C$12,MIN(COUNTIF(Tubos!$C$4:$C$12,"<"&M13)+1,9)),IF(D13="PE",INDEX(Tubos!$C$15:$C$21,MIN(COUNTIF(Tubos!$C$15:$C$21,"<"&M13)+1,7)),INDEX(Tubos!$C$24:$C$33,MIN(COUNTIF(Tubos!$C$24:$C$33,"<"&M13)+1,10)))) | P13: =K13/1000/(PI()*(O13/1000)^2/4) | Q13: 48 | R13: =Q13*Datos!$B$17 | S13: =P13*O13/1000/IF(C13="AF",Datos!$B$46,Datos!$B$47) | T13: =IF(S13<=0,0,0.25/(LOG10(Datos!$B$48/(3.7*O13/1000)+5.74/S13^0.9))^2) | U13: =IF(R13=0,0,T13*R13/(O13/1000)*P13^2/(2*Datos!$B$45)) | V13: 2.8 | W13: =V13*P13^2/(2*Datos!$B$45) | X13: =U13+W13
A14: MDL1 | B14: Montante directo O: tramo hasta planta 1 | C14: AF | D14: MC | E14: 84 | F14: 14 | G14: 0 | H14: 0 | I14: =IF(C14="AF",E14*Locales!$L$4+F14*Locales!$L$5+G14*Locales!$L$6,E14*Locales!$M$4+F14*Locales!$M$5+G14*Locales!$M$6)+H14 | J14: 0 | K14: =MAX(J14,IF(I14<=0,0,MIN(I14,IF(I14<=20,Datos!$B$25*I14^Datos!$C$25+Datos!$D$25,Datos!$B$26*I14^Datos!$C$26+Datos!$D$26)))) | L14: 1 | M14: =SQRT(4*K14/1000/(PI()*L14))*1000 | N14: =IF(D14="MC",INDEX(Tubos!$B$4:$B$12,MIN(COUNTIF(Tubos!$C$4:$C$12,"<"&M14)+1,9)),IF(D14="PE",INDEX(Tubos!$B$15:$B$21,MIN(COUNTIF(Tubos!$C$15:$C$21,"<"&M14)+1,7)),INDEX(Tubos!$B$24:$B$33,MIN(COUNTIF(Tubos!$C$24:$C$33,"<"&M14)+1,10)))) | O14: =IF(D14="MC",INDEX(Tubos!$C$4:$C$12,MIN(COUNTIF(Tubos!$C$4:$C$12,"<"&M14)+1,9)),IF(D14="PE",INDEX(Tubos!$C$15:$C$21,MIN(COUNTIF(Tubos!$C$15:$C$21,"<"&M14)+1,7)),INDEX(Tubos!$C$24:$C$33,MIN(COUNTIF(Tubos!$C$24:$C$33,"<"&M14)+1,10)))) | P14: =K14/1000/(PI()*(O14/1000)^2/4) | Q14: 7.3 | R14: =Q14*Datos!$B$17 | S14: =P14*O14/1000/IF(C14="AF",Datos!$B$46,Datos!$B$47) | T14: =IF(S14<=0,0,0.25/(LOG10(Datos!$B$48/(3.7*O14/1000)+5.74/S14^0.9))^2) | U14: =IF(R14=0,0,T14*R14/(O14/1000)*P14^2/(2*Datos!$B$45)) | V14: 0 | W14: =V14*P14^2/(2*Datos!$B$45) | X14: =U14+W14
A15: MDR1 | B15: Montante directo E: tramo hasta planta 1 | C15: AF | D15: MC | E15: 84 | F15: 0 | G15: 7 | H15: 0 | I15: =IF(C15="AF",E15*Locales!$L$4+F15*Locales!$L$5+G15*Locales!$L$6,E15*Locales!$M$4+F15*Locales!$M$5+G15*Locales!$M$6)+H15 | J15: 0 | K15: =MAX(J15,IF(I15<=0,0,MIN(I15,IF(I15<=20,Datos!$B$25*I15^Datos!$C$25+Datos!$D$25,Datos!$B$26*I15^Datos!$C$26+Datos!$D$26)))) | L15: 1 | M15: =SQRT(4*K15/1000/(PI()*L15))*1000 | N15: =IF(D15="MC",INDEX(Tubos!$B$4:$B$12,MIN(COUNTIF(Tubos!$C$4:$C$12,"<"&M15)+1,9)),IF(D15="PE",INDEX(Tubos!$B$15:$B$21,MIN(COUNTIF(Tubos!$C$15:$C$21,"<"&M15)+1,7)),INDEX(Tubos!$B$24:$B$33,MIN(COUNTIF(Tubos!$C$24:$C$33,"<"&M15)+1,10)))) | O15: =IF(D15="MC",INDEX(Tubos!$C$4:$C$12,MIN(COUNTIF(Tubos!$C$4:$C$12,"<"&M15)+1,9)),IF(D15="PE",INDEX(Tubos!$C$15:$C$21,MIN(COUNTIF(Tubos!$C$15:$C$21,"<"&M15)+1,7)),INDEX(Tubos!$C$24:$C$33,MIN(COUNTIF(Tubos!$C$24:$C$33,"<"&M15)+1,10)))) | P15: =K15/1000/(PI()*(O15/1000)^2/4) | Q15: 7.3 | R15: =Q15*Datos!$B$17 | S15: =P15*O15/1000/IF(C15="AF",Datos!$B$46,Datos!$B$47) | T15: =IF(S15<=0,0,0.25/(LOG10(Datos!$B$48/(3.7*O15/1000)+5.74/S15^0.9))^2) | U15: =IF(R15=0,0,T15*R15/(O15/1000)*P15^2/(2*Datos!$B$45)) | V15: 0 | W15: =V15*P15^2/(2*Datos!$B$45) | X15: =U15+W15
A16: MDL2 | B16: Montante directo O: tramo hasta planta 2 | C16: AF | D16: MC | E16: 72 | F16: 12 | G16: 0 | H16: 0 | I16: =IF(C16="AF",E16*Locales!$L$4+F16*Locales!$L$5+G16*Locales!$L$6,E16*Locales!$M$4+F16*Locales!$M$5+G16*Locales!$M$6)+H16 | J16: 0 | K16: =MAX(J16,IF(I16<=0,0,MIN(I16,IF(I16<=20,Datos!$B$25*I16^Datos!$C$25+Datos!$D$25,Datos!$B$26*I16^Datos!$C$26+Datos!$D$26)))) | L16: 1 | M16: =SQRT(4*K16/1000/(PI()*L16))*1000 | N16: =IF(D16="MC",INDEX(Tubos!$B$4:$B$12,MIN(COUNTIF(Tubos!$C$4:$C$12,"<"&M16)+1,9)),IF(D16="PE",INDEX(Tubos!$B$15:$B$21,MIN(COUNTIF(Tubos!$C$15:$C$21,"<"&M16)+1,7)),INDEX(Tubos!$B$24:$B$33,MIN(COUNTIF(Tubos!$C$24:$C$33,"<"&M16)+1,10)))) | O16: =IF(D16="MC",INDEX(Tubos!$C$4:$C$12,MIN(COUNTIF(Tubos!$C$4:$C$12,"<"&M16)+1,9)),IF(D16="PE",INDEX(Tubos!$C$15:$C$21,MIN(COUNTIF(Tubos!$C$15:$C$21,"<"&M16)+1,7)),INDEX(Tubos!$C$24:$C$33,MIN(COUNTIF(Tubos!$C$24:$C$33,"<"&M16)+1,10)))) | P16: =K16/1000/(PI()*(O16/1000)^2/4) | Q16: 3.3 | R16: =Q16*Datos!$B$17 | S16: =P16*O16/1000/IF(C16="AF",Datos!$B$46,Datos!$B$47) | T16: =IF(S16<=0,0,0.25/(LOG10(Datos!$B$48/(3.7*O16/1000)+5.74/S16^0.9))^2) | U16: =IF(R16=0,0,T16*R16/(O16/1000)*P16^2/(2*Datos!$B$45)) | V16: 0 | W16: =V16*P16^2/(2*Datos!$B$45) | X16: =U16+W16
A17: MDR2 | B17: Montante directo E: tramo hasta planta 2 | C17: AF | D17: MC | E17: 72 | F17: 0 | G17: 6 | H17: 0 | I17: =IF(C17="AF",E17*Locales!$L$4+F17*Locales!$L$5+G17*Locales!$L$6,E17*Locales!$M$4+F17*Locales!$M$5+G17*Locales!$M$6)+H17 | J17: 0 | K17: =MAX(J17,IF(I17<=0,0,MIN(I17,IF(I17<=20,Datos!$B$25*I17^Datos!$C$25+Datos!$D$25,Datos!$B$26*I17^Datos!$C$26+Datos!$D$26)))) | L17: 1 | M17: =SQRT(4*K17/1000/(PI()*L17))*1000 | N17: =IF(D17="MC",INDEX(Tubos!$B$4:$B$12,MIN(COUNTIF(Tubos!$C$4:$C$12,"<"&M17)+1,9)),IF(D17="PE",INDEX(Tubos!$B$15:$B$21,MIN(COUNTIF(Tubos!$C$15:$C$21,"<"&M17)+1,7)),INDEX(Tubos!$B$24:$B$33,MIN(COUNTIF(Tubos!$C$24:$C$33,"<"&M17)+1,10)))) | O17: =IF(D17="MC",INDEX(Tubos!$C$4:$C$12,MIN(COUNTIF(Tubos!$C$4:$C$12,"<"&M17)+1,9)),IF(D17="PE",INDEX(Tubos!$C$15:$C$21,MIN(COUNTIF(Tubos!$C$15:$C$21,"<"&M17)+1,7)),INDEX(Tubos!$C$24:$C$33,MIN(COUNTIF(Tubos!$C$24:$C$33,"<"&M17)+1,10)))) | P17: =K17/1000/(PI()*(O17/1000)^2/4) | Q17: 3.3 | R17: =Q17*Datos!$B$17 | S17: =P17*O17/1000/IF(C17="AF",Datos!$B$46,Datos!$B$47) | T17: =IF(S17<=0,0,0.25/(LOG10(Datos!$B$48/(3.7*O17/1000)+5.74/S17^0.9))^2) | U17: =IF(R17=0,0,T17*R17/(O17/1000)*P17^2/(2*Datos!$B$45)) | V17: 0 | W17: =V17*P17^2/(2*Datos!$B$45) | X17: =U17+W17
A18: MDL3 | B18: Montante directo O: tramo hasta planta 3 | C18: AF | D18: MC | E18: 60 | F18: 10 | G18: 0 | H18: 0 | I18: =IF(C18="AF",E18*Locales!$L$4+F18*Locales!$L$5+G18*Locales!$L$6,E18*Locales!$M$4+F18*Locales!$M$5+G18*Locales!$M$6)+H18 | J18: 0 | K18: =MAX(J18,IF(I18<=0,0,MIN(I18,IF(I18<=20,Datos!$B$25*I18^Datos!$C$25+Datos!$D$25,Datos!$B$26*I18^Datos!$C$26+Datos!$D$26)))) | L18: 1 | M18: =SQRT(4*K18/1000/(PI()*L18))*1000 | N18: =IF(D18="MC",INDEX(Tubos!$B$4:$B$12,MIN(COUNTIF(Tubos!$C$4:$C$12,"<"&M18)+1,9)),IF(D18="PE",INDEX(Tubos!$B$15:$B$21,MIN(COUNTIF(Tubos!$C$15:$C$21,"<"&M18)+1,7)),INDEX(Tubos!$B$24:$B$33,MIN(COUNTIF(Tubos!$C$24:$C$33,"<"&M18)+1,10)))) | O18: =IF(D18="MC",INDEX(Tubos!$C$4:$C$12,MIN(COUNTIF(Tubos!$C$4:$C$12,"<"&M18)+1,9)),IF(D18="PE",INDEX(Tubos!$C$15:$C$21,MIN(COUNTIF(Tubos!$C$15:$C$21,"<"&M18)+1,7)),INDEX(Tubos!$C$24:$C$33,MIN(COUNTIF(Tubos!$C$24:$C$33,"<"&M18)+1,10)))) | P18: =K18/1000/(PI()*(O18/1000)^2/4) | Q18: 3.3 | R18: =Q18*Datos!$B$17 | S18: =P18*O18/1000/IF(C18="AF",Datos!$B$46,Datos!$B$47) | T18: =IF(S18<=0,0,0.25/(LOG10(Datos!$B$48/(3.7*O18/1000)+5.74/S18^0.9))^2) | U18: =IF(R18=0,0,T18*R18/(O18/1000)*P18^2/(2*Datos!$B$45)) | V18: 0 | W18: =V18*P18^2/(2*Datos!$B$45) | X18: =U18+W18
A19: MDR3 | B19: Montante directo E: tramo hasta planta 3 | C19: AF | D19: MC | E19: 60 | F19: 0 | G19: 5 | H19: 0 | I19: =IF(C19="AF",E19*Locales!$L$4+F19*Locales!$L$5+G19*Locales!$L$6,E19*Locales!$M$4+F19*Locales!$M$5+G19*Locales!$M$6)+H19 | J19: 0 | K19: =MAX(J19,IF(I19<=0,0,MIN(I19,IF(I19<=20,Datos!$B$25*I19^Datos!$C$25+Datos!$D$25,Datos!$B$26*I19^Datos!$C$26+Datos!$D$26)))) | L19: 1 | M19: =SQRT(4*K19/1000/(PI()*L19))*1000 | N19: =IF(D19="MC",INDEX(Tubos!$B$4:$B$12,MIN(COUNTIF(Tubos!$C$4:$C$12,"<"&M19)+1,9)),IF(D19="PE",INDEX(Tubos!$B$15:$B$21,MIN(COUNTIF(Tubos!$C$15:$C$21,"<"&M19)+1,7)),INDEX(Tubos!$B$24:$B$33,MIN(COUNTIF(Tubos!$C$24:$C$33,"<"&M19)+1,10)))) | O19: =IF(D19="MC",INDEX(Tubos!$C$4:$C$12,MIN(COUNTIF(Tubos!$C$4:$C$12,"<"&M19)+1,9)),IF(D19="PE",INDEX(Tubos!$C$15:$C$21,MIN(COUNTIF(Tubos!$C$15:$C$21,"<"&M19)+1,7)),INDEX(Tubos!$C$24:$C$33,MIN(COUNTIF(Tubos!$C$24:$C$33,"<"&M19)+1,10)))) | P19: =K19/1000/(PI()*(O19/1000)^2/4) | Q19: 3.3 | R19: =Q19*Datos!$B$17 | S19: =P19*O19/1000/IF(C19="AF",Datos!$B$46,Datos!$B$47) | T19: =IF(S19<=0,0,0.25/(LOG10(Datos!$B$48/(3.7*O19/1000)+5.74/S19^0.9))^2) | U19: =IF(R19=0,0,T19*R19/(O19/1000)*P19^2/(2*Datos!$B$45)) | V19: 0 | W19: =V19*P19^2/(2*Datos!$B$45) | X19: =U19+W19
A20: MDL4 | B20: Montante directo O: tramo hasta planta 4 | C20: AF | D20: MC | E20: 48 | F20: 8 | G20: 0 | H20: 0 | I20: =IF(C20="AF",E20*Locales!$L$4+F20*Locales!$L$5+G20*Locales!$L$6,E20*Locales!$M$4+F20*Locales!$M$5+G20*Locales!$M$6)+H20 | J20: 0 | K20: =MAX(J20,IF(I20<=0,0,MIN(I20,IF(I20<=20,Datos!$B$25*I20^Datos!$C$25+Datos!$D$25,Datos!$B$26*I20^Datos!$C$26+Datos!$D$26)))) | L20: 1 | M20: =SQRT(4*K20/1000/(PI()*L20))*1000 | N20: =IF(D20="MC",INDEX(Tubos!$B$4:$B$12,MIN(COUNTIF(Tubos!$C$4:$C$12,"<"&M20)+1,9)),IF(D20="PE",INDEX(Tubos!$B$15:$B$21,MIN(COUNTIF(Tubos!$C$15:$C$21,"<"&M20)+1,7)),INDEX(Tubos!$B$24:$B$33,MIN(COUNTIF(Tubos!$C$24:$C$33,"<"&M20)+1,10)))) | O20: =IF(D20="MC",INDEX(Tubos!$C$4:$C$12,MIN(COUNTIF(Tubos!$C$4:$C$12,"<"&M20)+1,9)),IF(D20="PE",INDEX(Tubos!$C$15:$C$21,MIN(COUNTIF(Tubos!$C$15:$C$21,"<"&M20)+1,7)),INDEX(Tubos!$C$24:$C$33,MIN(COUNTIF(Tubos!$C$24:$C$33,"<"&M20)+1,10)))) | P20: =K20/1000/(PI()*(O20/1000)^2/4) | Q20: 3.3 | R20: =Q20*Datos!$B$17 | S20: =P20*O20/1000/IF(C20="AF",Datos!$B$46,Datos!$B$47) | T20: =IF(S20<=0,0,0.25/(LOG10(Datos!$B$48/(3.7*O20/1000)+5.74/S20^0.9))^2) | U20: =IF(R20=0,0,T20*R20/(O20/1000)*P20^2/(2*Datos!$B$45)) | V20: 0 | W20: =V20*P20^2/(2*Datos!$B$45) | X20: =U20+W20
A21: MDR4 | B21: Montante directo E: tramo hasta planta 4 | C21: AF | D21: MC | E21: 48 | F21: 0 | G21: 4 | H21: 0 | I21: =IF(C21="AF",E21*Locales!$L$4+F21*Locales!$L$5+G21*Locales!$L$6,E21*Locales!$M$4+F21*Locales!$M$5+G21*Locales!$M$6)+H21 | J21: 0 | K21: =MAX(J21,IF(I21<=0,0,MIN(I21,IF(I21<=20,Datos!$B$25*I21^Datos!$C$25+Datos!$D$25,Datos!$B$26*I21^Datos!$C$26+Datos!$D$26)))) | L21: 1 | M21: =SQRT(4*K21/1000/(PI()*L21))*1000 | N21: =IF(D21="MC",INDEX(Tubos!$B$4:$B$12,MIN(COUNTIF(Tubos!$C$4:$C$12,"<"&M21)+1,9)),IF(D21="PE",INDEX(Tubos!$B$15:$B$21,MIN(COUNTIF(Tubos!$C$15:$C$21,"<"&M21)+1,7)),INDEX(Tubos!$B$24:$B$33,MIN(COUNTIF(Tubos!$C$24:$C$33,"<"&M21)+1,10)))) | O21: =IF(D21="MC",INDEX(Tubos!$C$4:$C$12,MIN(COUNTIF(Tubos!$C$4:$C$12,"<"&M21)+1,9)),IF(D21="PE",INDEX(Tubos!$C$15:$C$21,MIN(COUNTIF(Tubos!$C$15:$C$21,"<"&M21)+1,7)),INDEX(Tubos!$C$24:$C$33,MIN(COUNTIF(Tubos!$C$24:$C$33,"<"&M21)+1,10)))) | P21: =K21/1000/(PI()*(O21/1000)^2/4) | Q21: 3.3 | R21: =Q21*Datos!$B$17 | S21: =P21*O21/1000/IF(C21="AF",Datos!$B$46,Datos!$B$47) | T21: =IF(S21<=0,0,0.25/(LOG10(Datos!$B$48/(3.7*O21/1000)+5.74/S21^0.9))^2) | U21: =IF(R21=0,0,T21*R21/(O21/1000)*P21^2/(2*Datos!$B$45)) | V21: 0 | W21: =V21*P21^2/(2*Datos!$B$45) | X21: =U21+W21
A22: MDL5 | B22: Montante directo O: tramo hasta planta 5 | C22: AF | D22: MC | E22: 36 | F22: 6 | G22: 0 | H22: 0 | I22: =IF(C22="AF",E22*Locales!$L$4+F22*Locales!$L$5+G22*Locales!$L$6,E22*Locales!$M$4+F22*Locales!$M$5+G22*Locales!$M$6)+H22 | J22: 0 | K22: =MAX(J22,IF(I22<=0,0,MIN(I22,IF(I22<=20,Datos!$B$25*I22^Datos!$C$25+Datos!$D$25,Datos!$B$26*I22^Datos!$C$26+Datos!$D$26)))) | L22: 1 | M22: =SQRT(4*K22/1000/(PI()*L22))*1000 | N22: =IF(D22="MC",INDEX(Tubos!$B$4:$B$12,MIN(COUNTIF(Tubos!$C$4:$C$12,"<"&M22)+1,9)),IF(D22="PE",INDEX(Tubos!$B$15:$B$21,MIN(COUNTIF(Tubos!$C$15:$C$21,"<"&M22)+1,7)),INDEX(Tubos!$B$24:$B$33,MIN(COUNTIF(Tubos!$C$24:$C$33,"<"&M22)+1,10)))) | O22: =IF(D22="MC",INDEX(Tubos!$C$4:$C$12,MIN(COUNTIF(Tubos!$C$4:$C$12,"<"&M22)+1,9)),IF(D22="PE",INDEX(Tubos!$C$15:$C$21,MIN(COUNTIF(Tubos!$C$15:$C$21,"<"&M22)+1,7)),INDEX(Tubos!$C$24:$C$33,MIN(COUNTIF(Tubos!$C$24:$C$33,"<"&M22)+1,10)))) | P22: =K22/1000/(PI()*(O22/1000)^2/4) | Q22: 3.3 | R22: =Q22*Datos!$B$17 | S22: =P22*O22/1000/IF(C22="AF",Datos!$B$46,Datos!$B$47) | T22: =IF(S22<=0,0,0.25/(LOG10(Datos!$B$48/(3.7*O22/1000)+5.74/S22^0.9))^2) | U22: =IF(R22=0,0,T22*R22/(O22/1000)*P22^2/(2*Datos!$B$45)) | V22: 0 | W22: =V22*P22^2/(2*Datos!$B$45) | X22: =U22+W22
A23: MDR5 | B23: Montante directo E: tramo hasta planta 5 | C23: AF | D23: MC | E23: 36 | F23: 0 | G23: 3 | H23: 0 | I23: =IF(C23="AF",E23*Locales!$L$4+F23*Locales!$L$5+G23*Locales!$L$6,E23*Locales!$M$4+F23*Locales!$M$5+G23*Locales!$M$6)+H23 | J23: 0 | K23: =MAX(J23,IF(I23<=0,0,MIN(I23,IF(I23<=20,Datos!$B$25*I23^Datos!$C$25+Datos!$D$25,Datos!$B$26*I23^Datos!$C$26+Datos!$D$26)))) | L23: 1 | M23: =SQRT(4*K23/1000/(PI()*L23))*1000 | N23: =IF(D23="MC",INDEX(Tubos!$B$4:$B$12,MIN(COUNTIF(Tubos!$C$4:$C$12,"<"&M23)+1,9)),IF(D23="PE",INDEX(Tubos!$B$15:$B$21,MIN(COUNTIF(Tubos!$C$15:$C$21,"<"&M23)+1,7)),INDEX(Tubos!$B$24:$B$33,MIN(COUNTIF(Tubos!$C$24:$C$33,"<"&M23)+1,10)))) | O23: =IF(D23="MC",INDEX(Tubos!$C$4:$C$12,MIN(COUNTIF(Tubos!$C$4:$C$12,"<"&M23)+1,9)),IF(D23="PE",INDEX(Tubos!$C$15:$C$21,MIN(COUNTIF(Tubos!$C$15:$C$21,"<"&M23)+1,7)),INDEX(Tubos!$C$24:$C$33,MIN(COUNTIF(Tubos!$C$24:$C$33,"<"&M23)+1,10)))) | P23: =K23/1000/(PI()*(O23/1000)^2/4) | Q23: 3.3 | R23: =Q23*Datos!$B$17 | S23: =P23*O23/1000/IF(C23="AF",Datos!$B$46,Datos!$B$47) | T23: =IF(S23<=0,0,0.25/(LOG10(Datos!$B$48/(3.7*O23/1000)+5.74/S23^0.9))^2) | U23: =IF(R23=0,0,T23*R23/(O23/1000)*P23^2/(2*Datos!$B$45)) | V23: 0 | W23: =V23*P23^2/(2*Datos!$B$45) | X23: =U23+W23
... A27: MDR7 | B27: Montante directo E: tramo hasta planta 7 | C27: AF | D27: MC | E27: 12 | F27: 0 | G27: 1 | H27: 0 | I27: =IF(C27="AF",E27*Locales!$L$4+F27*Locales!$L$5+G27*Locales!$L$6,E27*Locales!$M$4+F27*Locales!$M$5+G27*Locales!$M$6)+H27 | J27: 0 | K27: =MAX(J27,IF(I27<=0,0,MIN(I27,IF(I27<=20,Datos!$B$25*I27^Datos!$C$25+Datos!$D$25,Datos!$B$26*I27^Datos!$C$26+Datos!$D$26)))) | L27: 1 | M27: =SQRT(4*K27/1000/(PI()*L27))*1000 | N27: =IF(D27="MC",INDEX(Tubos!$B$4:$B$12,MIN(COUNTIF(Tubos!$C$4:$C$12,"<"&M27)+1,9)),IF(D27="PE",INDEX(Tubos!$B$15:$B$21,MIN(COUNTIF(Tubos!$C$15:$C$21,"<"&M27)+1,7)),INDEX(Tubos!$B$24:$B$33,MIN(COUNTIF(Tubos!$C$24:$C$33,"<"&M27)+1,10)))) | O27: =IF(D27="MC",INDEX(Tubos!$C$4:$C$12,MIN(COUNTIF(Tubos!$C$4:$C$12,"<"&M27)+1,9)),IF(D27="PE",INDEX(Tubos!$C$15:$C$21,MIN(COUNTIF(Tubos!$C$15:$C$21,"<"&M27)+1,7)),INDEX(Tubos!$C$24:$C$33,MIN(COUNTIF(Tubos!$C$24:$C$33,"<"&M27)+1,10)))) | P27: =K27/1000/(PI()*(O27/1000)^2/4) | Q27: 3.3 | R27: =Q27*Datos!$B$17 | S27: =P27*O27/1000/IF(C27="AF",Datos!$B$46,Datos!$B$47) | T27: =IF(S27<=0,0,0.25/(LOG10(Datos!$B$48/(3.7*O27/1000)+5.74/S27^0.9))^2) | U27: =IF(R27=0,0,T27*R27/(O27/1000)*P27^2/(2*Datos!$B$45)) | V27: 0 | W27: =V27*P27^2/(2*Datos!$B$45) | X27: =U27+W27
A28: BV0 | B28: Colector impulsión grupo (AF alta + alimentación ACS) | C28: AF | D28: MC | E28: 96 | F28: 8 | G28: 4 | H28: =Plantas!$R$17 | I28: =IF(C28="AF",E28*Locales!$L$4+F28*Locales!$L$5+G28*Locales!$L$6,E28*Locales!$M$4+F28*Locales!$M$5+G28*Locales!$M$6)+H28 | J28: 0 | K28: =MAX(J28,IF(I28<=0,0,MIN(I28,IF(I28<=20,Datos!$B$25*I28^Datos!$C$25+Datos!$D$25,Datos!$B$26*I28^Datos!$C$26+Datos!$D$26)))) | L28: 1 | M28: =SQRT(4*K28/1000/(PI()*L28))*1000 | N28: =IF(D28="MC",INDEX(Tubos!$B$4:$B$12,MIN(COUNTIF(Tubos!$C$4:$C$12,"<"&M28)+1,9)),IF(D28="PE",INDEX(Tubos!$B$15:$B$21,MIN(COUNTIF(Tubos!$C$15:$C$21,"<"&M28)+1,7)),INDEX(Tubos!$B$24:$B$33,MIN(COUNTIF(Tubos!$C$24:$C$33,"<"&M28)+1,10)))) | O28: =IF(D28="MC",INDEX(Tubos!$C$4:$C$12,MIN(COUNTIF(Tubos!$C$4:$C$12,"<"&M28)+1,9)),IF(D28="PE",INDEX(Tubos!$C$15:$C$21,MIN(COUNTIF(Tubos!$C$15:$C$21,"<"&M28)+1,7)),INDEX(Tubos!$C$24:$C$33,MIN(COUNTIF(Tubos!$C$24:$C$33,"<"&M28)+1,10)))) | P28: =K28/1000/(PI()*(O28/1000)^2/4) | Q28: 3 | R28: =Q28*Datos!$B$17 | S28: =P28*O28/1000/IF(C28="AF",Datos!$B$46,Datos!$B$47) | T28: =IF(S28<=0,0,0.25/(LOG10(Datos!$B$48/(3.7*O28/1000)+5.74/S28^0.9))^2) | U28: =IF(R28=0,0,T28*R28/(O28/1000)*P28^2/(2*Datos!$B$45)) | V28: 0.3 | W28: =V28*P28^2/(2*Datos!$B$45) | X28: =U28+W28
A29: BL1 | B29: Bombeo: cuarto AF → base patinillo O | C29: AF | D29: MC | E29: 48 | F29: 8 | G29: 0 | H29: 0 | I29: =IF(C29="AF",E29*Locales!$L$4+F29*Locales!$L$5+G29*Locales!$L$6,E29*Locales!$M$4+F29*Locales!$M$5+G29*Locales!$M$6)+H29 | J29: 0 | K29: =MAX(J29,IF(I29<=0,0,MIN(I29,IF(I29<=20,Datos!$B$25*I29^Datos!$C$25+Datos!$D$25,Datos!$B$26*I29^Datos!$C$26+Datos!$D$26)))) | L29: 1 | M29: =SQRT(4*K29/1000/(PI()*L29))*1000 | N29: =IF(D29="MC",INDEX(Tubos!$B$4:$B$12,MIN(COUNTIF(Tubos!$C$4:$C$12,"<"&M29)+1,9)),IF(D29="PE",INDEX(Tubos!$B$15:$B$21,MIN(COUNTIF(Tubos!$C$15:$C$21,"<"&M29)+1,7)),INDEX(Tubos!$B$24:$B$33,MIN(COUNTIF(Tubos!$C$24:$C$33,"<"&M29)+1,10)))) | O29: =IF(D29="MC",INDEX(Tubos!$C$4:$C$12,MIN(COUNTIF(Tubos!$C$4:$C$12,"<"&M29)+1,9)),IF(D29="PE",INDEX(Tubos!$C$15:$C$21,MIN(COUNTIF(Tubos!$C$15:$C$21,"<"&M29)+1,7)),INDEX(Tubos!$C$24:$C$33,MIN(COUNTIF(Tubos!$C$24:$C$33,"<"&M29)+1,10)))) | P29: =K29/1000/(PI()*(O29/1000)^2/4) | Q29: 12 | R29: =Q29*Datos!$B$17 | S29: =P29*O29/1000/IF(C29="AF",Datos!$B$46,Datos!$B$47) | T29: =IF(S29<=0,0,0.25/(LOG10(Datos!$B$48/(3.7*O29/1000)+5.74/S29^0.9))^2) | U29: =IF(R29=0,0,T29*R29/(O29/1000)*P29^2/(2*Datos!$B$45)) | V29: 2.8 | W29: =V29*P29^2/(2*Datos!$B$45) | X29: =U29+W29
